2025-08-17 16:17:35,446 - test - INFO - test_setup.py:64 - Test log message
2025-08-17 16:17:51,477 - core.config_manager - INFO - config_manager.py:36 - No config file found, using defaults
2025-08-17 16:17:51,478 - test - INFO - test_setup.py:65 - Test log message
2025-08-17 16:22:58,159 - kivy - WARNING - config.py:766 - Config: Older configuration version detected (0 instead of 27)
2025-08-17 16:22:58,159 - kivy - WARNING - config.py:769 - Config: Upgrading configuration in progress.
2025-08-17 16:22:58,160 - kivy - INFO - __init__.py:512 - Kivy: v2.3.1
2025-08-17 16:22:58,161 - kivy - INFO - __init__.py:513 - Kivy: Installed at "/Library/Frameworks/Python.framework/Versions/3.13/lib/python3.13/site-packages/kivy/__init__.py"
2025-08-17 16:22:58,161 - kivy - INFO - __init__.py:514 - Python: v3.13.4 (v3.13.4:8a526ec7cbe, Jun  3 2025, 21:14:54) [Clang 16.0.0 (clang-1600.0.26.6)]
2025-08-17 16:22:58,161 - kivy - INFO - __init__.py:515 - Python: Interpreter at "/Library/Frameworks/Python.framework/Versions/3.13/bin/python3"
2025-08-17 16:22:58,161 - kivy - INFO - logger.py:232 - Logger: Purge log fired. Processing...
2025-08-17 16:22:58,162 - kivy - INFO - logger.py:249 - Logger: Purge finished!
2025-08-17 16:22:58,350 - kivy - INFO - factory.py:186 - Factory: 195 symbols loaded
2025-08-17 16:22:58,976 - kivy - INFO - __init__.py:145 - Image: Providers: img_tex, img_imageio, img_dds, img_sdl2, img_pil (img_ffpyplayer ignored)
2025-08-17 16:22:59,212 - kivy - WARNING - logger.py:390 - stderr: Traceback (most recent call last):
2025-08-17 16:22:59,212 - kivy - WARNING - logger.py:390 - stderr:   File "/Users/parthchhabra/Desktop/StosOSRpi/stosos/test_framework.py", line 20, in <module>
2025-08-17 16:22:59,212 - kivy - WARNING - logger.py:390 - stderr:     from core.screen_manager import StosOSScreenManager
2025-08-17 16:22:59,212 - kivy - WARNING - logger.py:390 - stderr:   File "/Users/parthchhabra/Desktop/StosOSRpi/stosos/core/screen_manager.py", line 12, in <module>
2025-08-17 16:22:59,212 - kivy - WARNING - logger.py:390 - stderr:     from .base_module import BaseModule
2025-08-17 16:22:59,212 - kivy - WARNING - logger.py:390 - stderr:   File "/Users/parthchhabra/Desktop/StosOSRpi/stosos/core/base_module.py", line 9, in <module>
2025-08-17 16:22:59,212 - kivy - WARNING - logger.py:390 - stderr:     from kivy.uix.screen import Screen
2025-08-17 16:22:59,212 - kivy - WARNING - logger.py:390 - stderr: ModuleNotFoundError: No module named 'kivy.uix.screen'
2025-08-17 16:23:28,285 - kivy - INFO - __init__.py:512 - Kivy: v2.3.1
2025-08-17 16:23:28,285 - kivy - INFO - __init__.py:513 - Kivy: Installed at "/Library/Frameworks/Python.framework/Versions/3.13/lib/python3.13/site-packages/kivy/__init__.py"
2025-08-17 16:23:28,286 - kivy - INFO - __init__.py:514 - Python: v3.13.4 (v3.13.4:8a526ec7cbe, Jun  3 2025, 21:14:54) [Clang 16.0.0 (clang-1600.0.26.6)]
2025-08-17 16:23:28,286 - kivy - INFO - __init__.py:515 - Python: Interpreter at "/Library/Frameworks/Python.framework/Versions/3.13/bin/python3"
2025-08-17 16:23:28,286 - kivy - INFO - logger.py:232 - Logger: Purge log fired. Processing...
2025-08-17 16:23:28,286 - kivy - INFO - logger.py:249 - Logger: Purge finished!
2025-08-17 16:23:28,343 - kivy - INFO - factory.py:186 - Factory: 195 symbols loaded
2025-08-17 16:23:28,403 - kivy - INFO - __init__.py:145 - Image: Providers: img_tex, img_imageio, img_dds, img_sdl2, img_pil (img_ffpyplayer ignored)
2025-08-17 16:23:28,530 - kivy - INFO - __init__.py:67 - Text: Provider: sdl2
2025-08-17 16:23:28,539 - core.config_manager - INFO - config_manager.py:36 - No config file found, using defaults
2025-08-17 16:23:28,539 - core.config_manager - DEBUG - config_manager.py:109 - Config updated: test.value = test_data
2025-08-17 16:23:28,539 - core.config_manager - DEBUG - config_manager.py:109 - Config updated: api_keys.test_service = test_key_123
2025-08-17 16:23:28,539 - core.error_handler - WARNING - error_handler.py:209 - Error in Test context: Test error for framework testing (Type: system, Module: )
2025-08-17 16:23:28,539 - core.error_handler - DEBUG - error_handler.py:215 - Full traceback: Traceback (most recent call last):
  File "/Users/parthchhabra/Desktop/StosOSRpi/stosos/test_framework.py", line 58, in test_error_handler
    raise ValueError("Test error for framework testing")
ValueError: Test error for framework testing

2025-08-17 16:23:28,540 - core.error_handler - DEBUG - error_handler.py:229 - No recovery strategy available for system
2025-08-17 16:23:28,540 - stosos.modules.test_module - INFO - test_module.py:28 - Initializing test module
2025-08-17 16:23:28,574 - kivy - INFO - __init__.py:67 - Window: Provider: sdl2
2025-08-17 16:23:29,418 - kivy - INFO - __init__.py:45 - GL: Using the "OpenGL ES 2" graphics system
2025-08-17 16:23:29,418 - kivy - INFO - __init__.py:51 - GL: Backend used <sdl2>
2025-08-17 16:23:29,419 - kivy - INFO - __init__.py:55 - GL: OpenGL version <b'2.1 Metal - 90.5'>
2025-08-17 16:23:29,419 - kivy - INFO - __init__.py:56 - GL: OpenGL vendor <b'Apple'>
2025-08-17 16:23:29,419 - kivy - INFO - __init__.py:57 - GL: OpenGL renderer <b'Apple M2'>
2025-08-17 16:23:29,419 - kivy - INFO - __init__.py:61 - GL: OpenGL parsed version: 2, 1
2025-08-17 16:23:29,419 - kivy - INFO - __init__.py:81 - GL: Shading version <b'1.20'>
2025-08-17 16:23:29,419 - kivy - INFO - __init__.py:83 - GL: Texture max size <16384>
2025-08-17 16:23:29,419 - kivy - INFO - __init__.py:85 - GL: Texture max units <16>
2025-08-17 16:23:29,446 - kivy - INFO - window_sdl2.py:369 - Window: auto add sdl2 input provider
2025-08-17 16:23:29,478 - kivy - INFO - __init__.py:2308 - Window: virtual keyboard not allowed, single mode, not docked
2025-08-17 16:23:29,484 - stosos.modules.test_module - INFO - test_module.py:65 - Test module initialized successfully
2025-08-17 16:23:29,484 - stosos.modules.test_module - INFO - test_module.py:93 - Test module received voice command: test command
2025-08-17 16:23:29,485 - stosos.modules.test_module - DEBUG - base_module.py:52 - Module test_module activated
2025-08-17 16:23:29,485 - stosos.modules.test_module - DEBUG - base_module.py:61 - Module test_module deactivated
2025-08-17 16:23:29,485 - stosos.modules.test_module - DEBUG - base_module.py:91 - Module test_module cleaned up
2025-08-17 16:23:29,485 - stosos.modules.test_module - INFO - test_module.py:28 - Initializing test module
2025-08-17 16:23:29,486 - stosos.modules.test_module - INFO - test_module.py:65 - Test module initialized successfully
2025-08-17 16:23:29,486 - core.screen_manager - INFO - screen_manager.py:65 - Module registered successfully: test_module
2025-08-17 16:23:29,486 - stosos.modules.test_module - DEBUG - base_module.py:91 - Module test_module cleaned up
2025-08-17 16:23:29,486 - core.screen_manager - INFO - screen_manager.py:104 - Module unregistered successfully: test_module
2025-08-17 16:24:02,381 - kivy - INFO - __init__.py:512 - Kivy: v2.3.1
2025-08-17 16:24:02,382 - kivy - INFO - __init__.py:513 - Kivy: Installed at "/Library/Frameworks/Python.framework/Versions/3.13/lib/python3.13/site-packages/kivy/__init__.py"
2025-08-17 16:24:02,382 - kivy - INFO - __init__.py:514 - Python: v3.13.4 (v3.13.4:8a526ec7cbe, Jun  3 2025, 21:14:54) [Clang 16.0.0 (clang-1600.0.26.6)]
2025-08-17 16:24:02,382 - kivy - INFO - __init__.py:515 - Python: Interpreter at "/Library/Frameworks/Python.framework/Versions/3.13/bin/python3"
2025-08-17 16:24:02,382 - kivy - INFO - logger.py:232 - Logger: Purge log fired. Processing...
2025-08-17 16:24:02,383 - kivy - INFO - logger.py:249 - Logger: Purge finished!
2025-08-17 16:24:02,438 - kivy - INFO - factory.py:186 - Factory: 195 symbols loaded
2025-08-17 16:24:02,565 - kivy - INFO - __init__.py:145 - Image: Providers: img_tex, img_imageio, img_dds, img_sdl2, img_pil (img_ffpyplayer ignored)
2025-08-17 16:24:02,595 - kivy - INFO - __init__.py:67 - Text: Provider: sdl2
2025-08-17 16:24:02,608 - core.config_manager - INFO - config_manager.py:36 - No config file found, using defaults
2025-08-17 16:24:02,620 - kivy - INFO - __init__.py:67 - Window: Provider: sdl2
2025-08-17 16:24:03,055 - kivy - INFO - __init__.py:45 - GL: Using the "OpenGL ES 2" graphics system
2025-08-17 16:24:03,056 - kivy - INFO - __init__.py:51 - GL: Backend used <sdl2>
2025-08-17 16:24:03,056 - kivy - INFO - __init__.py:55 - GL: OpenGL version <b'2.1 Metal - 90.5'>
2025-08-17 16:24:03,056 - kivy - INFO - __init__.py:56 - GL: OpenGL vendor <b'Apple'>
2025-08-17 16:24:03,057 - kivy - INFO - __init__.py:57 - GL: OpenGL renderer <b'Apple M2'>
2025-08-17 16:24:03,057 - kivy - INFO - __init__.py:61 - GL: OpenGL parsed version: 2, 1
2025-08-17 16:24:03,057 - kivy - INFO - __init__.py:81 - GL: Shading version <b'1.20'>
2025-08-17 16:24:03,057 - kivy - INFO - __init__.py:83 - GL: Texture max size <16384>
2025-08-17 16:24:03,057 - kivy - INFO - __init__.py:85 - GL: Texture max units <16>
2025-08-17 16:24:03,071 - kivy - INFO - window_sdl2.py:369 - Window: auto add sdl2 input provider
2025-08-17 16:24:03,091 - kivy - INFO - __init__.py:2308 - Window: virtual keyboard not allowed, single mode, not docked
2025-08-17 16:25:15,499 - stosos.modules.test_module - INFO - test_module.py:28 - Initializing test module
2025-08-17 16:25:16,560 - stosos.modules.test_module - INFO - test_module.py:65 - Test module initialized successfully
2025-08-17 16:25:16,560 - stosos.modules.test_module - INFO - test_module.py:93 - Test module received voice command: test command
2025-08-17 16:25:16,561 - stosos.modules.test_module - INFO - test_module.py:28 - Initializing test module
2025-08-17 16:25:16,561 - stosos.modules.test_module - INFO - test_module.py:65 - Test module initialized successfully
2025-08-17 16:25:16,561 - core.screen_manager - INFO - screen_manager.py:65 - Module registered successfully: test_module
2025-08-17 16:25:16,561 - core.screen_manager - INFO - screen_manager.py:104 - Module unregistered successfully: test_module
2025-08-17 16:25:16,562 - core.config_manager - INFO - config_manager.py:36 - No config file found, using defaults
2025-08-17 16:25:16,562 - core.config_manager - INFO - config_manager.py:79 - Configuration saved successfully
2025-08-17 16:25:16,563 - core.error_handler - INFO - error_handler.py:211 - Error in Verification test: Test error for verification (Type: system, Module: )
2025-08-17 16:30:16,345 - stosos.modules.ui_demo - INFO - ui_demo.py:37 - Initializing UI Demo module
2025-08-17 16:31:14,238 - stosos.modules.ui_demo - INFO - ui_demo.py:37 - Initializing UI Demo module
2025-08-17 16:32:14,126 - stosos.modules.ui_demo - INFO - ui_demo.py:37 - Initializing UI Demo module
2025-08-17 16:32:51,204 - stosos.modules.ui_demo - INFO - ui_demo.py:37 - Initializing UI Demo module
2025-08-17 16:33:46,682 - stosos.modules.ui_demo - INFO - ui_demo.py:37 - Initializing UI Demo module
2025-08-17 16:36:36,108 - __main__ - INFO - main.py:268 - Starting StosOS application
2025-08-17 16:36:36,109 - __main__ - INFO - main.py:48 - Starting StosOS Desktop Environment
2025-08-17 16:36:36,110 - core.config_manager - INFO - config_manager.py:30 - Configuration loaded successfully
2025-08-17 16:36:36,117 - __main__ - INFO - main.py:127 - Main interface created
2025-08-17 16:36:36,117 - __main__ - INFO - main.py:86 - Application initialized successfully
2025-08-17 16:36:36,120 - __main__ - INFO - main.py:136 - Application started - showing branding sequence
2025-08-17 16:36:36,120 - ui.branding_screen - INFO - branding_screen.py:347 - Showing branding screen
2025-08-17 16:36:36,134 - ui.branding_screen - INFO - branding_screen.py:152 - Starting branding animation sequence
2025-08-17 16:36:40,313 - ui.branding_screen - INFO - branding_screen.py:215 - Starting initialization sequence
2025-08-17 16:36:45,825 - ui.branding_screen - INFO - branding_screen.py:258 - Branding sequence complete, transitioning to main interface
2025-08-17 16:36:46,444 - ui.branding_screen - INFO - branding_screen.py:366 - Branding screen completed
2025-08-17 16:36:46,445 - __main__ - INFO - main.py:154 - Branding complete - initializing main interface
2025-08-17 16:36:46,446 - stosos.modules.test_module - INFO - test_module.py:28 - Initializing test module
2025-08-17 16:36:46,451 - stosos.modules.test_module - INFO - test_module.py:65 - Test module initialized successfully
2025-08-17 16:36:46,452 - core.screen_manager - INFO - screen_manager.py:65 - Module registered successfully: test_module
2025-08-17 16:36:46,452 - __main__ - INFO - main.py:250 - Module registered with application: test_module
2025-08-17 16:36:46,452 - __main__ - INFO - main.py:173 - Test module registered successfully
2025-08-17 16:36:46,452 - stosos.modules.ui_demo - INFO - ui_demo.py:37 - Initializing UI Demo module
2025-08-17 16:36:46,475 - core.screen_manager - INFO - screen_manager.py:65 - Module registered successfully: ui_demo
2025-08-17 16:36:46,475 - __main__ - INFO - main.py:250 - Module registered with application: ui_demo
2025-08-17 16:36:46,475 - __main__ - INFO - main.py:180 - UI Demo module registered successfully
2025-08-17 16:36:46,475 - __main__ - INFO - main.py:206 - Transitioned to main interface
2025-08-17 16:36:47,051 - stosos.modules.ui_demo - INFO - ui_demo.py:369 - UI Demo module activated
2025-08-17 16:37:00,381 - __main__ - ERROR - main.py:272 - Application failed to start: StosOSButton._on_touch_up() takes 2 positional arguments but 3 were given
2025-08-17 16:43:33,133 - core.power_manager - WARNING - power_manager.py:421 - No brightness control method detected
2025-08-17 16:43:33,135 - core.power_manager - INFO - power_manager.py:86 - PowerManager initialized
2025-08-17 16:43:33,138 - core.power_manager - WARNING - power_manager.py:421 - No brightness control method detected
2025-08-17 16:43:33,138 - core.power_manager - INFO - power_manager.py:86 - PowerManager initialized
2025-08-17 16:43:33,141 - core.power_manager - WARNING - power_manager.py:421 - No brightness control method detected
2025-08-17 16:43:33,142 - core.power_manager - INFO - power_manager.py:86 - PowerManager initialized
2025-08-17 16:43:33,142 - core.power_manager - INFO - power_manager.py:222 - Forcing display sleep
2025-08-17 16:43:33,142 - core.power_manager - INFO - power_manager.py:362 - Power state changed: active -> sleep
2025-08-17 16:43:33,142 - core.power_manager - WARNING - power_manager.py:381 - No brightness control method available
2025-08-17 16:43:33,142 - core.power_manager - INFO - power_manager.py:196 - Waking display from sleep (source: test)
2025-08-17 16:43:33,142 - core.power_manager - INFO - power_manager.py:362 - Power state changed: sleep -> wake
2025-08-17 16:43:33,348 - core.power_manager - WARNING - power_manager.py:381 - No brightness control method available
2025-08-17 16:43:33,348 - core.power_manager - INFO - power_manager.py:236 - Brightness manually set to 50%
2025-08-17 16:43:33,348 - core.power_manager - INFO - power_manager.py:196 - Waking display from wake (source: user_activity)
2025-08-17 16:43:34,453 - core.power_manager - INFO - power_manager.py:196 - Waking display from wake (source: user_activity)
2025-08-17 16:43:34,454 - core.power_manager - INFO - power_manager.py:196 - Waking display from wake (source: user_activity)
2025-08-17 16:43:34,454 - core.power_manager - INFO - power_manager.py:196 - Waking display from wake (source: user_activity)
2025-08-17 16:43:34,455 - core.power_manager - INFO - power_manager.py:222 - Forcing display sleep
2025-08-17 16:43:34,455 - core.power_manager - INFO - power_manager.py:362 - Power state changed: wake -> sleep
2025-08-17 16:43:34,455 - core.power_manager - WARNING - power_manager.py:381 - No brightness control method available
2025-08-17 16:43:34,455 - core.power_manager - INFO - power_manager.py:196 - Waking display from sleep (source: manual)
2025-08-17 16:43:34,455 - core.power_manager - INFO - power_manager.py:362 - Power state changed: sleep -> wake
2025-08-17 16:43:34,660 - core.power_manager - INFO - power_manager.py:196 - Waking display from wake (source: user_activity)
2025-08-17 16:43:34,661 - core.power_manager - INFO - power_manager.py:196 - Waking display from wake (source: user_activity)
2025-08-17 16:43:34,661 - core.power_manager - WARNING - power_manager.py:381 - No brightness control method available
2025-08-17 16:43:34,661 - core.power_manager - INFO - power_manager.py:236 - Brightness manually set to 0%
2025-08-17 16:43:34,662 - core.power_manager - INFO - power_manager.py:362 - Power state changed: wake -> active
2025-08-17 16:43:34,663 - core.power_manager - WARNING - power_manager.py:381 - No brightness control method available
2025-08-17 16:43:34,663 - core.power_manager - INFO - power_manager.py:107 - Power management monitoring started
2025-08-17 16:43:35,168 - core.power_manager - WARNING - power_manager.py:381 - No brightness control method available
2025-08-17 16:43:35,169 - core.power_manager - INFO - power_manager.py:236 - Brightness manually set to 50%
2025-08-17 16:43:35,169 - core.power_manager - WARNING - power_manager.py:381 - No brightness control method available
2025-08-17 16:43:35,169 - core.power_manager - INFO - power_manager.py:236 - Brightness manually set to 50%
2025-08-17 16:43:35,169 - core.power_manager - WARNING - power_manager.py:381 - No brightness control method available
2025-08-17 16:43:35,169 - core.power_manager - INFO - power_manager.py:236 - Brightness manually set to 50%
2025-08-17 16:43:35,181 - core.power_manager - WARNING - power_manager.py:381 - No brightness control method available
2025-08-17 16:43:35,182 - core.power_manager - INFO - power_manager.py:236 - Brightness manually set to 51%
2025-08-17 16:43:35,182 - core.power_manager - WARNING - power_manager.py:381 - No brightness control method available
2025-08-17 16:43:35,182 - core.power_manager - INFO - power_manager.py:236 - Brightness manually set to 51%
2025-08-17 16:43:35,182 - core.power_manager - WARNING - power_manager.py:381 - No brightness control method available
2025-08-17 16:43:35,182 - core.power_manager - INFO - power_manager.py:236 - Brightness manually set to 51%
2025-08-17 16:43:35,195 - core.power_manager - WARNING - power_manager.py:381 - No brightness control method available
2025-08-17 16:43:35,195 - core.power_manager - INFO - power_manager.py:236 - Brightness manually set to 52%
2025-08-17 16:43:35,195 - core.power_manager - WARNING - power_manager.py:381 - No brightness control method available
2025-08-17 16:43:35,196 - core.power_manager - INFO - power_manager.py:236 - Brightness manually set to 52%
2025-08-17 16:43:35,196 - core.power_manager - WARNING - power_manager.py:381 - No brightness control method available
2025-08-17 16:43:35,196 - core.power_manager - INFO - power_manager.py:236 - Brightness manually set to 52%
2025-08-17 16:43:35,207 - core.power_manager - WARNING - power_manager.py:381 - No brightness control method available
2025-08-17 16:43:35,208 - core.power_manager - INFO - power_manager.py:236 - Brightness manually set to 53%
2025-08-17 16:43:35,208 - core.power_manager - WARNING - power_manager.py:381 - No brightness control method available
2025-08-17 16:43:35,208 - core.power_manager - INFO - power_manager.py:236 - Brightness manually set to 53%
2025-08-17 16:43:35,209 - core.power_manager - WARNING - power_manager.py:381 - No brightness control method available
2025-08-17 16:43:35,209 - core.power_manager - INFO - power_manager.py:236 - Brightness manually set to 53%
2025-08-17 16:43:35,220 - core.power_manager - WARNING - power_manager.py:381 - No brightness control method available
2025-08-17 16:43:35,220 - core.power_manager - INFO - power_manager.py:236 - Brightness manually set to 54%
2025-08-17 16:43:35,221 - core.power_manager - WARNING - power_manager.py:381 - No brightness control method available
2025-08-17 16:43:35,221 - core.power_manager - INFO - power_manager.py:236 - Brightness manually set to 54%
2025-08-17 16:43:35,221 - core.power_manager - WARNING - power_manager.py:381 - No brightness control method available
2025-08-17 16:43:35,221 - core.power_manager - INFO - power_manager.py:236 - Brightness manually set to 54%
2025-08-17 16:43:35,233 - core.power_manager - WARNING - power_manager.py:381 - No brightness control method available
2025-08-17 16:43:35,233 - core.power_manager - INFO - power_manager.py:236 - Brightness manually set to 55%
2025-08-17 16:43:35,233 - core.power_manager - WARNING - power_manager.py:381 - No brightness control method available
2025-08-17 16:43:35,233 - core.power_manager - INFO - power_manager.py:236 - Brightness manually set to 55%
2025-08-17 16:43:35,234 - core.power_manager - WARNING - power_manager.py:381 - No brightness control method available
2025-08-17 16:43:35,234 - core.power_manager - INFO - power_manager.py:236 - Brightness manually set to 55%
2025-08-17 16:43:35,245 - core.power_manager - WARNING - power_manager.py:381 - No brightness control method available
2025-08-17 16:43:35,246 - core.power_manager - INFO - power_manager.py:236 - Brightness manually set to 56%
2025-08-17 16:43:35,246 - core.power_manager - WARNING - power_manager.py:381 - No brightness control method available
2025-08-17 16:43:35,246 - core.power_manager - INFO - power_manager.py:236 - Brightness manually set to 56%
2025-08-17 16:43:35,246 - core.power_manager - WARNING - power_manager.py:381 - No brightness control method available
2025-08-17 16:43:35,246 - core.power_manager - INFO - power_manager.py:236 - Brightness manually set to 56%
2025-08-17 16:43:35,259 - core.power_manager - WARNING - power_manager.py:381 - No brightness control method available
2025-08-17 16:43:35,259 - core.power_manager - INFO - power_manager.py:236 - Brightness manually set to 57%
2025-08-17 16:43:35,259 - core.power_manager - WARNING - power_manager.py:381 - No brightness control method available
2025-08-17 16:43:35,259 - core.power_manager - INFO - power_manager.py:236 - Brightness manually set to 57%
2025-08-17 16:43:35,259 - core.power_manager - WARNING - power_manager.py:381 - No brightness control method available
2025-08-17 16:43:35,259 - core.power_manager - INFO - power_manager.py:236 - Brightness manually set to 57%
2025-08-17 16:43:35,270 - core.power_manager - WARNING - power_manager.py:381 - No brightness control method available
2025-08-17 16:43:35,270 - core.power_manager - INFO - power_manager.py:236 - Brightness manually set to 58%
2025-08-17 16:43:35,271 - core.power_manager - WARNING - power_manager.py:381 - No brightness control method available
2025-08-17 16:43:35,271 - core.power_manager - INFO - power_manager.py:236 - Brightness manually set to 58%
2025-08-17 16:43:35,272 - core.power_manager - WARNING - power_manager.py:381 - No brightness control method available
2025-08-17 16:43:35,272 - core.power_manager - INFO - power_manager.py:236 - Brightness manually set to 58%
2025-08-17 16:43:35,281 - core.power_manager - WARNING - power_manager.py:381 - No brightness control method available
2025-08-17 16:43:35,282 - core.power_manager - INFO - power_manager.py:236 - Brightness manually set to 59%
2025-08-17 16:43:35,282 - core.power_manager - WARNING - power_manager.py:381 - No brightness control method available
2025-08-17 16:43:35,282 - core.power_manager - INFO - power_manager.py:236 - Brightness manually set to 59%
2025-08-17 16:43:35,282 - core.power_manager - WARNING - power_manager.py:381 - No brightness control method available
2025-08-17 16:43:35,282 - core.power_manager - INFO - power_manager.py:236 - Brightness manually set to 59%
2025-08-17 16:43:35,664 - core.power_manager - WARNING - power_manager.py:381 - No brightness control method available
2025-08-17 16:43:35,664 - core.power_manager - INFO - power_manager.py:125 - Power management monitoring stopped
2025-08-17 16:43:35,665 - core.power_manager - WARNING - power_manager.py:381 - No brightness control method available
2025-08-17 16:43:35,665 - core.power_manager - INFO - power_manager.py:125 - Power management monitoring stopped
2025-08-17 16:44:11,351 - core.power_manager - WARNING - power_manager.py:421 - No brightness control method detected
2025-08-17 16:44:11,352 - core.power_manager - INFO - power_manager.py:86 - PowerManager initialized
2025-08-17 16:44:11,355 - core.power_manager - WARNING - power_manager.py:421 - No brightness control method detected
2025-08-17 16:44:11,355 - core.power_manager - INFO - power_manager.py:86 - PowerManager initialized
2025-08-17 16:44:11,358 - core.power_manager - WARNING - power_manager.py:421 - No brightness control method detected
2025-08-17 16:44:11,358 - core.power_manager - INFO - power_manager.py:86 - PowerManager initialized
2025-08-17 16:44:11,358 - core.power_manager - INFO - power_manager.py:222 - Forcing display sleep
2025-08-17 16:44:11,359 - core.power_manager - INFO - power_manager.py:362 - Power state changed: active -> sleep
2025-08-17 16:44:11,359 - core.power_manager - WARNING - power_manager.py:381 - No brightness control method available
2025-08-17 16:44:11,359 - core.power_manager - INFO - power_manager.py:196 - Waking display from sleep (source: test)
2025-08-17 16:44:11,359 - core.power_manager - INFO - power_manager.py:362 - Power state changed: sleep -> wake
2025-08-17 16:44:11,564 - core.power_manager - WARNING - power_manager.py:381 - No brightness control method available
2025-08-17 16:44:11,565 - core.power_manager - INFO - power_manager.py:236 - Brightness manually set to 50%
2025-08-17 16:44:11,565 - core.power_manager - INFO - power_manager.py:196 - Waking display from wake (source: user_activity)
2025-08-17 16:44:12,671 - core.power_manager - INFO - power_manager.py:196 - Waking display from wake (source: user_activity)
2025-08-17 16:44:12,672 - core.power_manager - INFO - power_manager.py:196 - Waking display from wake (source: user_activity)
2025-08-17 16:44:12,672 - core.power_manager - INFO - power_manager.py:196 - Waking display from wake (source: user_activity)
2025-08-17 16:44:12,672 - core.power_manager - INFO - power_manager.py:222 - Forcing display sleep
2025-08-17 16:44:12,672 - core.power_manager - INFO - power_manager.py:362 - Power state changed: wake -> sleep
2025-08-17 16:44:12,672 - core.power_manager - WARNING - power_manager.py:381 - No brightness control method available
2025-08-17 16:44:12,672 - core.power_manager - INFO - power_manager.py:196 - Waking display from sleep (source: manual)
2025-08-17 16:44:12,673 - core.power_manager - INFO - power_manager.py:362 - Power state changed: sleep -> wake
2025-08-17 16:44:12,878 - core.power_manager - INFO - power_manager.py:196 - Waking display from wake (source: user_activity)
2025-08-17 16:44:12,879 - core.power_manager - INFO - power_manager.py:196 - Waking display from wake (source: user_activity)
2025-08-17 16:44:12,879 - core.power_manager - WARNING - power_manager.py:381 - No brightness control method available
2025-08-17 16:44:12,879 - core.power_manager - INFO - power_manager.py:236 - Brightness manually set to 0%
2025-08-17 16:44:12,880 - core.power_manager - INFO - power_manager.py:362 - Power state changed: wake -> active
2025-08-17 16:44:12,880 - core.power_manager - WARNING - power_manager.py:381 - No brightness control method available
2025-08-17 16:44:12,880 - core.power_manager - INFO - power_manager.py:107 - Power management monitoring started
2025-08-17 16:44:13,381 - core.power_manager - WARNING - power_manager.py:381 - No brightness control method available
2025-08-17 16:44:13,382 - core.power_manager - INFO - power_manager.py:236 - Brightness manually set to 50%
2025-08-17 16:44:13,382 - core.power_manager - WARNING - power_manager.py:381 - No brightness control method available
2025-08-17 16:44:13,383 - core.power_manager - INFO - power_manager.py:236 - Brightness manually set to 50%
2025-08-17 16:44:13,384 - core.power_manager - WARNING - power_manager.py:381 - No brightness control method available
2025-08-17 16:44:13,384 - core.power_manager - INFO - power_manager.py:236 - Brightness manually set to 50%
2025-08-17 16:44:13,395 - core.power_manager - WARNING - power_manager.py:381 - No brightness control method available
2025-08-17 16:44:13,395 - core.power_manager - INFO - power_manager.py:236 - Brightness manually set to 51%
2025-08-17 16:44:13,396 - core.power_manager - WARNING - power_manager.py:381 - No brightness control method available
2025-08-17 16:44:13,396 - core.power_manager - INFO - power_manager.py:236 - Brightness manually set to 51%
2025-08-17 16:44:13,396 - core.power_manager - WARNING - power_manager.py:381 - No brightness control method available
2025-08-17 16:44:13,396 - core.power_manager - INFO - power_manager.py:236 - Brightness manually set to 51%
2025-08-17 16:44:13,406 - core.power_manager - WARNING - power_manager.py:381 - No brightness control method available
2025-08-17 16:44:13,407 - core.power_manager - INFO - power_manager.py:236 - Brightness manually set to 52%
2025-08-17 16:44:13,407 - core.power_manager - WARNING - power_manager.py:381 - No brightness control method available
2025-08-17 16:44:13,407 - core.power_manager - INFO - power_manager.py:236 - Brightness manually set to 52%
2025-08-17 16:44:13,409 - core.power_manager - WARNING - power_manager.py:381 - No brightness control method available
2025-08-17 16:44:13,409 - core.power_manager - INFO - power_manager.py:236 - Brightness manually set to 52%
2025-08-17 16:44:13,418 - core.power_manager - WARNING - power_manager.py:381 - No brightness control method available
2025-08-17 16:44:13,419 - core.power_manager - INFO - power_manager.py:236 - Brightness manually set to 53%
2025-08-17 16:44:13,419 - core.power_manager - WARNING - power_manager.py:381 - No brightness control method available
2025-08-17 16:44:13,419 - core.power_manager - INFO - power_manager.py:236 - Brightness manually set to 53%
2025-08-17 16:44:13,420 - core.power_manager - WARNING - power_manager.py:381 - No brightness control method available
2025-08-17 16:44:13,420 - core.power_manager - INFO - power_manager.py:236 - Brightness manually set to 53%
2025-08-17 16:44:13,431 - core.power_manager - WARNING - power_manager.py:381 - No brightness control method available
2025-08-17 16:44:13,432 - core.power_manager - INFO - power_manager.py:236 - Brightness manually set to 54%
2025-08-17 16:44:13,432 - core.power_manager - WARNING - power_manager.py:381 - No brightness control method available
2025-08-17 16:44:13,432 - core.power_manager - INFO - power_manager.py:236 - Brightness manually set to 54%
2025-08-17 16:44:13,432 - core.power_manager - WARNING - power_manager.py:381 - No brightness control method available
2025-08-17 16:44:13,432 - core.power_manager - INFO - power_manager.py:236 - Brightness manually set to 54%
2025-08-17 16:44:13,444 - core.power_manager - WARNING - power_manager.py:381 - No brightness control method available
2025-08-17 16:44:13,444 - core.power_manager - INFO - power_manager.py:236 - Brightness manually set to 55%
2025-08-17 16:44:13,444 - core.power_manager - WARNING - power_manager.py:381 - No brightness control method available
2025-08-17 16:44:13,445 - core.power_manager - INFO - power_manager.py:236 - Brightness manually set to 55%
2025-08-17 16:44:13,445 - core.power_manager - WARNING - power_manager.py:381 - No brightness control method available
2025-08-17 16:44:13,445 - core.power_manager - INFO - power_manager.py:236 - Brightness manually set to 55%
2025-08-17 16:44:13,455 - core.power_manager - WARNING - power_manager.py:381 - No brightness control method available
2025-08-17 16:44:13,455 - core.power_manager - INFO - power_manager.py:236 - Brightness manually set to 56%
2025-08-17 16:44:13,457 - core.power_manager - WARNING - power_manager.py:381 - No brightness control method available
2025-08-17 16:44:13,457 - core.power_manager - INFO - power_manager.py:236 - Brightness manually set to 56%
2025-08-17 16:44:13,457 - core.power_manager - WARNING - power_manager.py:381 - No brightness control method available
2025-08-17 16:44:13,458 - core.power_manager - INFO - power_manager.py:236 - Brightness manually set to 56%
2025-08-17 16:44:13,468 - core.power_manager - WARNING - power_manager.py:381 - No brightness control method available
2025-08-17 16:44:13,468 - core.power_manager - INFO - power_manager.py:236 - Brightness manually set to 57%
2025-08-17 16:44:13,469 - core.power_manager - WARNING - power_manager.py:381 - No brightness control method available
2025-08-17 16:44:13,469 - core.power_manager - INFO - power_manager.py:236 - Brightness manually set to 57%
2025-08-17 16:44:13,469 - core.power_manager - WARNING - power_manager.py:381 - No brightness control method available
2025-08-17 16:44:13,469 - core.power_manager - INFO - power_manager.py:236 - Brightness manually set to 57%
2025-08-17 16:44:13,481 - core.power_manager - WARNING - power_manager.py:381 - No brightness control method available
2025-08-17 16:44:13,481 - core.power_manager - INFO - power_manager.py:236 - Brightness manually set to 58%
2025-08-17 16:44:13,482 - core.power_manager - WARNING - power_manager.py:381 - No brightness control method available
2025-08-17 16:44:13,482 - core.power_manager - INFO - power_manager.py:236 - Brightness manually set to 58%
2025-08-17 16:44:13,482 - core.power_manager - WARNING - power_manager.py:381 - No brightness control method available
2025-08-17 16:44:13,482 - core.power_manager - INFO - power_manager.py:236 - Brightness manually set to 58%
2025-08-17 16:44:13,493 - core.power_manager - WARNING - power_manager.py:381 - No brightness control method available
2025-08-17 16:44:13,493 - core.power_manager - INFO - power_manager.py:236 - Brightness manually set to 59%
2025-08-17 16:44:13,494 - core.power_manager - WARNING - power_manager.py:381 - No brightness control method available
2025-08-17 16:44:13,494 - core.power_manager - INFO - power_manager.py:236 - Brightness manually set to 59%
2025-08-17 16:44:13,494 - core.power_manager - WARNING - power_manager.py:381 - No brightness control method available
2025-08-17 16:44:13,494 - core.power_manager - INFO - power_manager.py:236 - Brightness manually set to 59%
2025-08-17 16:44:13,885 - core.power_manager - WARNING - power_manager.py:381 - No brightness control method available
2025-08-17 16:44:13,885 - core.power_manager - INFO - power_manager.py:125 - Power management monitoring stopped
2025-08-17 16:44:13,886 - core.power_manager - WARNING - power_manager.py:381 - No brightness control method available
2025-08-17 16:44:13,886 - core.power_manager - INFO - power_manager.py:125 - Power management monitoring stopped
2025-08-17 16:44:50,142 - core.power_manager - WARNING - power_manager.py:429 - No brightness control method detected
2025-08-17 16:44:50,143 - core.power_manager - INFO - power_manager.py:86 - PowerManager initialized
2025-08-17 16:44:50,146 - core.power_manager - WARNING - power_manager.py:429 - No brightness control method detected
2025-08-17 16:44:50,146 - core.power_manager - INFO - power_manager.py:86 - PowerManager initialized
2025-08-17 16:44:50,150 - core.power_manager - WARNING - power_manager.py:429 - No brightness control method detected
2025-08-17 16:44:50,150 - core.power_manager - INFO - power_manager.py:86 - PowerManager initialized
2025-08-17 16:44:50,150 - core.power_manager - INFO - power_manager.py:226 - Forcing display sleep
2025-08-17 16:44:50,150 - core.power_manager - INFO - power_manager.py:366 - Power state changed: active -> sleep
2025-08-17 16:44:50,150 - core.power_manager - INFO - power_manager.py:196 - Waking display from sleep (source: test)
2025-08-17 16:44:50,150 - core.power_manager - INFO - power_manager.py:366 - Power state changed: sleep -> wake
2025-08-17 16:44:50,351 - core.power_manager - INFO - power_manager.py:240 - Brightness manually set to 50%
2025-08-17 16:44:50,351 - core.power_manager - INFO - power_manager.py:240 - Brightness manually set to 0%
2025-08-17 16:44:50,351 - core.power_manager - INFO - power_manager.py:240 - Brightness manually set to 100%
2025-08-17 16:44:50,351 - core.power_manager - INFO - power_manager.py:240 - Brightness manually set to 0%
2025-08-17 16:44:50,351 - core.power_manager - INFO - power_manager.py:240 - Brightness manually set to 100%
2025-08-17 16:44:50,352 - core.power_manager - INFO - power_manager.py:240 - Brightness manually set to 0%
2025-08-17 16:44:50,352 - core.power_manager - INFO - power_manager.py:196 - Waking display from wake (source: user_activity)
2025-08-17 16:44:51,457 - core.power_manager - INFO - power_manager.py:196 - Waking display from wake (source: user_activity)
2025-08-17 16:44:51,458 - core.power_manager - INFO - power_manager.py:196 - Waking display from wake (source: user_activity)
2025-08-17 16:44:51,458 - core.power_manager - INFO - power_manager.py:196 - Waking display from wake (source: user_activity)
2025-08-17 16:44:51,458 - core.power_manager - INFO - power_manager.py:226 - Forcing display sleep
2025-08-17 16:44:51,459 - core.power_manager - INFO - power_manager.py:366 - Power state changed: wake -> sleep
2025-08-17 16:44:51,459 - core.power_manager - INFO - power_manager.py:196 - Waking display from sleep (source: manual)
2025-08-17 16:44:51,459 - core.power_manager - INFO - power_manager.py:366 - Power state changed: sleep -> wake
2025-08-17 16:44:51,663 - core.power_manager - INFO - power_manager.py:196 - Waking display from wake (source: user_activity)
2025-08-17 16:44:51,664 - core.power_manager - INFO - power_manager.py:196 - Waking display from wake (source: user_activity)
2025-08-17 16:44:51,664 - core.power_manager - INFO - power_manager.py:240 - Brightness manually set to 0%
2025-08-17 16:44:51,664 - core.power_manager - INFO - power_manager.py:240 - Brightness manually set to 100%
2025-08-17 16:44:51,666 - core.power_manager - INFO - power_manager.py:366 - Power state changed: wake -> active
2025-08-17 16:44:51,666 - core.power_manager - INFO - power_manager.py:107 - Power management monitoring started
2025-08-17 16:44:52,167 - core.power_manager - INFO - power_manager.py:240 - Brightness manually set to 50%
2025-08-17 16:44:52,167 - core.power_manager - INFO - power_manager.py:240 - Brightness manually set to 50%
2025-08-17 16:44:52,167 - core.power_manager - INFO - power_manager.py:240 - Brightness manually set to 50%
2025-08-17 16:44:52,178 - core.power_manager - INFO - power_manager.py:240 - Brightness manually set to 51%
2025-08-17 16:44:52,180 - core.power_manager - INFO - power_manager.py:240 - Brightness manually set to 51%
2025-08-17 16:44:52,180 - core.power_manager - INFO - power_manager.py:240 - Brightness manually set to 51%
2025-08-17 16:44:52,191 - core.power_manager - INFO - power_manager.py:240 - Brightness manually set to 52%
2025-08-17 16:44:52,192 - core.power_manager - INFO - power_manager.py:240 - Brightness manually set to 52%
2025-08-17 16:44:52,193 - core.power_manager - INFO - power_manager.py:240 - Brightness manually set to 52%
2025-08-17 16:44:52,204 - core.power_manager - INFO - power_manager.py:240 - Brightness manually set to 53%
2025-08-17 16:44:52,204 - core.power_manager - INFO - power_manager.py:240 - Brightness manually set to 53%
2025-08-17 16:44:52,204 - core.power_manager - INFO - power_manager.py:240 - Brightness manually set to 53%
2025-08-17 16:44:52,217 - core.power_manager - INFO - power_manager.py:240 - Brightness manually set to 54%
2025-08-17 16:44:52,217 - core.power_manager - INFO - power_manager.py:240 - Brightness manually set to 54%
2025-08-17 16:44:52,217 - core.power_manager - INFO - power_manager.py:240 - Brightness manually set to 54%
2025-08-17 16:44:52,230 - core.power_manager - INFO - power_manager.py:240 - Brightness manually set to 55%
2025-08-17 16:44:52,230 - core.power_manager - INFO - power_manager.py:240 - Brightness manually set to 55%
2025-08-17 16:44:52,230 - core.power_manager - INFO - power_manager.py:240 - Brightness manually set to 55%
2025-08-17 16:44:52,243 - core.power_manager - INFO - power_manager.py:240 - Brightness manually set to 56%
2025-08-17 16:44:52,243 - core.power_manager - INFO - power_manager.py:240 - Brightness manually set to 56%
2025-08-17 16:44:52,243 - core.power_manager - INFO - power_manager.py:240 - Brightness manually set to 56%
2025-08-17 16:44:52,255 - core.power_manager - INFO - power_manager.py:240 - Brightness manually set to 57%
2025-08-17 16:44:52,255 - core.power_manager - INFO - power_manager.py:240 - Brightness manually set to 57%
2025-08-17 16:44:52,255 - core.power_manager - INFO - power_manager.py:240 - Brightness manually set to 57%
2025-08-17 16:44:52,268 - core.power_manager - INFO - power_manager.py:240 - Brightness manually set to 58%
2025-08-17 16:44:52,268 - core.power_manager - INFO - power_manager.py:240 - Brightness manually set to 58%
2025-08-17 16:44:52,268 - core.power_manager - INFO - power_manager.py:240 - Brightness manually set to 58%
2025-08-17 16:44:52,281 - core.power_manager - INFO - power_manager.py:240 - Brightness manually set to 59%
2025-08-17 16:44:52,281 - core.power_manager - INFO - power_manager.py:240 - Brightness manually set to 59%
2025-08-17 16:44:52,282 - core.power_manager - INFO - power_manager.py:240 - Brightness manually set to 59%
2025-08-17 16:44:52,669 - core.power_manager - INFO - power_manager.py:125 - Power management monitoring stopped
2025-08-17 16:44:52,669 - core.power_manager - INFO - power_manager.py:125 - Power management monitoring stopped
2025-08-17 16:45:34,800 - core.power_manager - WARNING - power_manager.py:434 - No brightness control method detected
2025-08-17 16:45:34,801 - core.power_manager - INFO - power_manager.py:86 - PowerManager initialized
2025-08-17 16:45:34,804 - core.power_manager - WARNING - power_manager.py:434 - No brightness control method detected
2025-08-17 16:45:34,804 - core.power_manager - INFO - power_manager.py:86 - PowerManager initialized
2025-08-17 16:45:34,807 - core.power_manager - WARNING - power_manager.py:434 - No brightness control method detected
2025-08-17 16:45:34,807 - core.power_manager - INFO - power_manager.py:86 - PowerManager initialized
2025-08-17 16:45:34,807 - core.power_manager - INFO - power_manager.py:231 - Forcing display sleep
2025-08-17 16:45:34,807 - core.power_manager - INFO - power_manager.py:371 - Power state changed: active -> sleep
2025-08-17 16:45:34,807 - core.power_manager - INFO - power_manager.py:196 - Waking display from sleep (source: test)
2025-08-17 16:45:34,807 - core.power_manager - INFO - power_manager.py:371 - Power state changed: sleep -> wake
2025-08-17 16:54:29,161 - core.power_manager - WARNING - power_manager.py:440 - No brightness control method detected
2025-08-17 16:54:29,162 - core.power_manager - INFO - power_manager.py:86 - PowerManager initialized
2025-08-17 16:54:29,166 - core.power_manager - WARNING - power_manager.py:440 - No brightness control method detected
2025-08-17 16:54:29,166 - core.power_manager - INFO - power_manager.py:86 - PowerManager initialized
2025-08-17 16:54:29,169 - core.power_manager - WARNING - power_manager.py:440 - No brightness control method detected
2025-08-17 16:54:29,169 - core.power_manager - INFO - power_manager.py:86 - PowerManager initialized
2025-08-17 16:54:29,169 - core.power_manager - INFO - power_manager.py:237 - Forcing display sleep
2025-08-17 16:54:29,170 - core.power_manager - INFO - power_manager.py:377 - Power state changed: active -> sleep
2025-08-17 16:54:29,170 - core.power_manager - INFO - power_manager.py:196 - Waking display from sleep (source: test)
2025-08-17 16:54:29,170 - core.power_manager - INFO - power_manager.py:377 - Power state changed: sleep -> wake
2025-08-17 16:57:02,710 - core.power_manager - WARNING - power_manager.py:439 - No brightness control method detected
2025-08-17 16:57:02,710 - core.power_manager - INFO - power_manager.py:86 - PowerManager initialized
2025-08-17 16:57:02,713 - core.power_manager - WARNING - power_manager.py:439 - No brightness control method detected
2025-08-17 16:57:02,713 - core.power_manager - INFO - power_manager.py:86 - PowerManager initialized
2025-08-17 16:57:02,714 - core.power_manager - INFO - power_manager.py:250 - Brightness manually set to 50%
2025-08-17 16:57:02,714 - core.power_manager - INFO - power_manager.py:250 - Brightness manually set to 0%
2025-08-17 16:57:02,714 - core.power_manager - INFO - power_manager.py:250 - Brightness manually set to 100%
2025-08-17 16:57:02,714 - core.power_manager - INFO - power_manager.py:236 - Forcing display sleep
2025-08-17 16:57:02,714 - core.power_manager - INFO - power_manager.py:376 - Power state changed: active -> sleep
2025-08-17 16:57:02,714 - core.power_manager - INFO - power_manager.py:376 - Power state changed: sleep -> active
2025-08-17 16:58:07,459 - core.power_manager - WARNING - power_manager.py:439 - No brightness control method detected
2025-08-17 16:58:07,460 - core.power_manager - INFO - power_manager.py:86 - PowerManager initialized
2025-08-17 16:58:08,707 - core.config_manager - INFO - config_manager.py:30 - Configuration loaded successfully
2025-08-17 16:58:08,716 - core.power_manager - WARNING - power_manager.py:439 - No brightness control method detected
2025-08-17 16:58:08,716 - core.power_manager - INFO - power_manager.py:86 - PowerManager initialized
2025-08-17 16:58:08,717 - kivy - WARNING - logger.py:390 - stderr: Traceback (most recent call last):
2025-08-17 16:58:08,717 - kivy - WARNING - logger.py:390 - stderr:   File "/Users/parthchhabra/Desktop/StosOSRpi/stosos/test_power_integration.py", line 60, in test_power_integration
2025-08-17 16:58:08,717 - kivy - WARNING - logger.py:390 - stderr:     demo_module = PowerDemoModule()
2025-08-17 16:58:08,717 - kivy - WARNING - logger.py:390 - stderr: TypeError: Can't instantiate abstract class PowerDemoModule without an implementation for abstract methods 'get_screen', 'initialize'
2025-08-17 16:58:26,477 - core.power_manager - WARNING - power_manager.py:439 - No brightness control method detected
2025-08-17 16:58:26,477 - core.power_manager - INFO - power_manager.py:86 - PowerManager initialized
2025-08-17 16:58:26,719 - core.config_manager - INFO - config_manager.py:30 - Configuration loaded successfully
2025-08-17 16:58:26,725 - core.power_manager - WARNING - power_manager.py:439 - No brightness control method detected
2025-08-17 16:58:26,725 - core.power_manager - INFO - power_manager.py:86 - PowerManager initialized
2025-08-17 16:58:26,726 - kivy - WARNING - logger.py:390 - stderr: Traceback (most recent call last):
2025-08-17 16:58:26,726 - kivy - WARNING - logger.py:390 - stderr:   File "/Users/parthchhabra/Desktop/StosOSRpi/stosos/test_power_integration.py", line 60, in test_power_integration
2025-08-17 16:58:26,726 - kivy - WARNING - logger.py:390 - stderr:     demo_module = PowerDemoModule()
2025-08-17 16:58:26,726 - kivy - WARNING - logger.py:390 - stderr:   File "/Users/parthchhabra/Desktop/StosOSRpi/stosos/modules/power_demo.py", line 24, in __init__
2025-08-17 16:58:26,726 - kivy - WARNING - logger.py:390 - stderr:     super().__init__(
2025-08-17 16:58:26,726 - kivy - WARNING - logger.py:390 - stderr:     ~~~~~~~~~~~~~~~~^
2025-08-17 16:58:26,726 - kivy - WARNING - logger.py:390 - stderr:         module_id="power_demo",
2025-08-17 16:58:26,726 - kivy - WARNING - logger.py:390 - stderr:         ^^^^^^^^^^^^^^^^^^^^^^^
2025-08-17 16:58:26,726 - kivy - WARNING - logger.py:390 - stderr:         name="Power Management Demo",
2025-08-17 16:58:26,726 - kivy - WARNING - logger.py:390 - stderr:         ^^^^^^^^^^^^^^^^^^^^^^^^^^^^^
2025-08-17 16:58:26,726 - kivy - WARNING - logger.py:390 - stderr:         description="Interactive demonstration of power management features"
2025-08-17 16:58:26,726 - kivy - WARNING - logger.py:390 - stderr:         ^^^^^^^^^^^^^^^^^^^^^^^^^^^^^^^^^^^^^^^^^^^^^^^^^^^^^^^^^^^^^^^^^^^^
2025-08-17 16:58:26,726 - kivy - WARNING - logger.py:390 - stderr:     )
2025-08-17 16:58:26,726 - kivy - WARNING - logger.py:390 - stderr:     ^
2025-08-17 16:58:26,726 - kivy - WARNING - logger.py:390 - stderr: TypeError: BaseModule.__init__() got an unexpected keyword argument 'name'
2025-08-17 16:58:50,991 - core.power_manager - WARNING - power_manager.py:439 - No brightness control method detected
2025-08-17 16:58:50,991 - core.power_manager - INFO - power_manager.py:86 - PowerManager initialized
2025-08-17 16:58:51,230 - core.config_manager - INFO - config_manager.py:30 - Configuration loaded successfully
2025-08-17 16:58:51,236 - core.power_manager - WARNING - power_manager.py:439 - No brightness control method detected
2025-08-17 16:58:51,236 - core.power_manager - INFO - power_manager.py:86 - PowerManager initialized
2025-08-17 16:58:51,250 - core.power_manager - INFO - power_manager.py:236 - Forcing display sleep
2025-08-17 16:58:51,250 - core.power_manager - INFO - power_manager.py:376 - Power state changed: active -> sleep
2025-08-17 16:58:51,250 - core.power_manager - INFO - power_manager.py:376 - Power state changed: sleep -> active
2025-08-17 16:58:51,250 - core.power_manager - INFO - power_manager.py:250 - Brightness manually set to 0%
2025-08-17 16:58:51,250 - core.power_manager - INFO - power_manager.py:250 - Brightness manually set to 100%
2025-08-17 16:58:51,250 - core.power_manager - INFO - power_manager.py:250 - Brightness manually set to 50%
2025-08-17 16:58:51,251 - core.power_manager - INFO - power_manager.py:250 - Brightness manually set to 50%
2025-08-17 16:58:51,262 - core.power_manager - INFO - power_manager.py:250 - Brightness manually set to 51%
2025-08-17 16:58:51,262 - core.power_manager - INFO - power_manager.py:250 - Brightness manually set to 51%
2025-08-17 16:58:51,274 - core.power_manager - INFO - power_manager.py:250 - Brightness manually set to 52%
2025-08-17 16:58:51,274 - core.power_manager - INFO - power_manager.py:250 - Brightness manually set to 52%
2025-08-17 16:58:51,286 - core.power_manager - INFO - power_manager.py:250 - Brightness manually set to 53%
2025-08-17 16:58:51,287 - core.power_manager - INFO - power_manager.py:250 - Brightness manually set to 53%
2025-08-17 16:58:51,298 - core.power_manager - INFO - power_manager.py:250 - Brightness manually set to 54%
2025-08-17 16:58:51,298 - core.power_manager - INFO - power_manager.py:250 - Brightness manually set to 54%
2025-08-17 16:58:51,311 - stosos.modules.power_demo - INFO - power_demo.py:277 - Power demo module cleaned up
2025-08-17 16:58:51,311 - core.power_manager - INFO - power_manager.py:125 - Power management monitoring stopped
2025-08-17 16:59:46,140 - core.power_manager - WARNING - power_manager.py:439 - No brightness control method detected
2025-08-17 16:59:46,141 - core.power_manager - INFO - power_manager.py:86 - PowerManager initialized
2025-08-17 16:59:47,337 - core.power_manager - WARNING - power_manager.py:439 - No brightness control method detected
2025-08-17 16:59:47,337 - core.power_manager - INFO - power_manager.py:86 - PowerManager initialized
2025-08-17 16:59:47,337 - core.power_manager - INFO - power_manager.py:250 - Brightness manually set to 100%
2025-08-17 16:59:47,338 - core.power_manager - INFO - power_manager.py:250 - Brightness manually set to 75%
2025-08-17 16:59:47,338 - core.power_manager - INFO - power_manager.py:250 - Brightness manually set to 50%
2025-08-17 16:59:47,338 - core.power_manager - INFO - power_manager.py:250 - Brightness manually set to 25%
2025-08-17 16:59:47,338 - core.power_manager - INFO - power_manager.py:250 - Brightness manually set to 0%
2025-08-17 16:59:47,338 - core.power_manager - INFO - power_manager.py:250 - Brightness manually set to 100%
2025-08-17 16:59:47,338 - core.power_manager - INFO - power_manager.py:236 - Forcing display sleep
2025-08-17 16:59:47,338 - core.power_manager - INFO - power_manager.py:376 - Power state changed: active -> sleep
2025-08-17 16:59:47,338 - core.power_manager - INFO - power_manager.py:376 - Power state changed: sleep -> active
2025-08-17 16:59:47,338 - core.power_manager - INFO - power_manager.py:236 - Forcing display sleep
2025-08-17 16:59:47,338 - core.power_manager - INFO - power_manager.py:376 - Power state changed: active -> sleep
2025-08-17 16:59:47,338 - core.power_manager - INFO - power_manager.py:195 - Waking display from sleep (source: manual)
2025-08-17 16:59:47,339 - core.power_manager - INFO - power_manager.py:376 - Power state changed: sleep -> active
2025-08-17 16:59:47,339 - core.power_manager - INFO - power_manager.py:236 - Forcing display sleep
2025-08-17 16:59:47,339 - core.power_manager - INFO - power_manager.py:376 - Power state changed: active -> sleep
2025-08-17 16:59:47,339 - core.power_manager - INFO - power_manager.py:195 - Waking display from sleep (source: touch)
2025-08-17 16:59:47,339 - core.power_manager - INFO - power_manager.py:376 - Power state changed: sleep -> active
2025-08-17 16:59:47,339 - core.power_manager - INFO - power_manager.py:236 - Forcing display sleep
2025-08-17 16:59:47,340 - core.power_manager - INFO - power_manager.py:376 - Power state changed: active -> sleep
2025-08-17 16:59:47,340 - core.power_manager - INFO - power_manager.py:195 - Waking display from sleep (source: voice)
2025-08-17 16:59:47,340 - core.power_manager - INFO - power_manager.py:376 - Power state changed: sleep -> active
2025-08-17 16:59:47,340 - core.power_manager - INFO - power_manager.py:236 - Forcing display sleep
2025-08-17 16:59:47,340 - core.power_manager - INFO - power_manager.py:376 - Power state changed: active -> sleep
2025-08-17 16:59:47,340 - core.power_manager - INFO - power_manager.py:195 - Waking display from sleep (source: network)
2025-08-17 16:59:47,340 - core.power_manager - INFO - power_manager.py:376 - Power state changed: sleep -> active
2025-08-17 16:59:48,441 - stosos.modules.power_demo - INFO - power_demo.py:39 - Initializing power management demo module
2025-08-17 16:59:48,471 - core.config_manager - INFO - config_manager.py:30 - Configuration loaded successfully
2025-08-17 16:59:48,471 - core.power_manager - INFO - power_manager.py:125 - Power management monitoring stopped
2025-08-17 16:59:48,471 - stosos.modules.power_demo - INFO - power_demo.py:277 - Power demo module cleaned up
2025-08-17 17:06:46,788 - core.power_manager - WARNING - power_manager.py:439 - No brightness control method detected
2025-08-17 17:06:46,789 - core.power_manager - INFO - power_manager.py:86 - PowerManager initialized
2025-08-17 17:06:46,881 - kivy - WARNING - logger.py:390 - stderr: Traceback (most recent call last):
2025-08-17 17:06:46,882 - kivy - WARNING - logger.py:390 - stderr:   File "/Users/parthchhabra/Desktop/StosOSRpi/stosos/test_database_simple.py", line 11, in <module>
2025-08-17 17:06:46,882 - kivy - WARNING - logger.py:390 - stderr:     from core.database_manager import DatabaseManager
2025-08-17 17:06:46,882 - kivy - WARNING - logger.py:390 - stderr:   File "/Users/parthchhabra/Desktop/StosOSRpi/stosos/core/database_manager.py", line 16, in <module>
2025-08-17 17:06:46,882 - kivy - WARNING - logger.py:390 - stderr:     from ..models import Task, Idea, StudySession, SmartDevice
2025-08-17 17:06:46,882 - kivy - WARNING - logger.py:390 - stderr: ImportError: attempted relative import beyond top-level package
2025-08-17 17:08:17,354 - core.power_manager - WARNING - power_manager.py:439 - No brightness control method detected
2025-08-17 17:08:17,354 - core.power_manager - INFO - power_manager.py:86 - PowerManager initialized
2025-08-17 17:08:32,646 - core.power_manager - WARNING - power_manager.py:439 - No brightness control method detected
2025-08-17 17:08:32,647 - core.power_manager - INFO - power_manager.py:86 - PowerManager initialized
2025-08-17 17:09:26,875 - core.power_manager - WARNING - power_manager.py:439 - No brightness control method detected
2025-08-17 17:09:26,879 - core.power_manager - INFO - power_manager.py:86 - PowerManager initialized
2025-08-17 17:15:48,586 - core.power_manager - WARNING - power_manager.py:439 - No brightness control method detected
2025-08-17 17:15:48,587 - core.power_manager - INFO - power_manager.py:86 - PowerManager initialized
2025-08-17 17:15:48,593 - kivy - WARNING - logger.py:390 - stderr: test_approaching_deadlines (__main__.TestTaskManagerCore.test_approaching_deadlines)
2025-08-17 17:15:48,594 - kivy - WARNING - logger.py:390 - stderr: Test approaching deadlines detection ... ok
2025-08-17 17:15:48,594 - kivy - WARNING - logger.py:390 - stderr: test_create_task (__main__.TestTaskManagerCore.test_create_task)
2025-08-17 17:15:48,594 - kivy - WARNING - logger.py:390 - stderr: Test creating new task ... ok
2025-08-17 17:15:48,594 - kivy - WARNING - logger.py:390 - stderr: test_delete_task (__main__.TestTaskManagerCore.test_delete_task)
2025-08-17 17:15:48,594 - kivy - WARNING - logger.py:390 - stderr: Test deleting task ... ok
2025-08-17 17:15:48,594 - kivy - WARNING - logger.py:390 - stderr: test_filter_by_category (__main__.TestTaskManagerCore.test_filter_by_category)
2025-08-17 17:15:48,594 - kivy - WARNING - logger.py:390 - stderr: Test filtering tasks by category ... ok
2025-08-17 17:15:48,595 - kivy - WARNING - logger.py:390 - stderr: test_filter_by_completion_status (__main__.TestTaskManagerCore.test_filter_by_completion_status)
2025-08-17 17:15:48,595 - kivy - WARNING - logger.py:390 - stderr: Test filtering tasks by completion status ... ok
2025-08-17 17:15:48,595 - kivy - WARNING - logger.py:390 - stderr: test_filter_by_priority (__main__.TestTaskManagerCore.test_filter_by_priority)
2025-08-17 17:15:48,595 - kivy - WARNING - logger.py:390 - stderr: Test filtering tasks by priority ... ok
2025-08-17 17:15:48,595 - kivy - WARNING - logger.py:390 - stderr: test_initialization (__main__.TestTaskManagerCore.test_initialization)
2025-08-17 17:15:48,595 - kivy - WARNING - logger.py:390 - stderr: Test core initialization ... ok
2025-08-17 17:15:48,595 - kivy - WARNING - logger.py:390 - stderr: test_search_functionality (__main__.TestTaskManagerCore.test_search_functionality)
2025-08-17 17:15:48,595 - kivy - WARNING - logger.py:390 - stderr: Test search functionality ... ok
2025-08-17 17:15:48,595 - kivy - WARNING - logger.py:390 - stderr: test_sorting (__main__.TestTaskManagerCore.test_sorting)
2025-08-17 17:15:48,596 - kivy - WARNING - logger.py:390 - stderr: Test task sorting functionality ... FAIL
2025-08-17 17:15:48,596 - kivy - WARNING - logger.py:390 - stderr: test_statistics (__main__.TestTaskManagerCore.test_statistics)
2025-08-17 17:15:48,596 - kivy - WARNING - logger.py:390 - stderr: Test statistics calculation ... FAIL
2025-08-17 17:15:48,596 - kivy - WARNING - logger.py:390 - stderr: test_toggle_completion (__main__.TestTaskManagerCore.test_toggle_completion)
2025-08-17 17:15:48,596 - kivy - WARNING - logger.py:390 - stderr: Test toggling task completion ... ok
2025-08-17 17:15:48,596 - kivy - WARNING - logger.py:390 - stderr: test_update_task (__main__.TestTaskManagerCore.test_update_task)
2025-08-17 17:15:48,597 - kivy - WARNING - logger.py:390 - stderr: Test updating existing task ... ok
2025-08-17 17:15:48,597 - kivy - WARNING - logger.py:390 - stderr: test_voice_commands (__main__.TestTaskManagerCore.test_voice_commands)
2025-08-17 17:15:48,597 - kivy - WARNING - logger.py:390 - stderr: Test voice command handling ... ok
2025-08-17 17:15:48,597 - kivy - WARNING - logger.py:390 - stderr: test_filtering_and_sorting_integration (__main__.TestTaskManagerIntegration.test_filtering_and_sorting_integration)
2025-08-17 17:15:48,600 - kivy - WARNING - logger.py:390 - stderr: Test filtering and sorting with real data ... ok
2025-08-17 17:15:48,600 - kivy - WARNING - logger.py:390 - stderr: test_full_task_lifecycle (__main__.TestTaskManagerIntegration.test_full_task_lifecycle)
2025-08-17 17:15:48,600 - kivy - WARNING - logger.py:390 - stderr: Test complete task lifecycle ... ok
2025-08-17 17:15:48,600 - kivy - WARNING - logger.py:390 - stderr: 
2025-08-17 17:15:48,600 - kivy - WARNING - logger.py:390 - stderr: ======================================================================
2025-08-17 17:15:48,600 - kivy - WARNING - logger.py:390 - stderr: FAIL: test_sorting (__main__.TestTaskManagerCore.test_sorting)
2025-08-17 17:15:48,600 - kivy - WARNING - logger.py:390 - stderr: Test task sorting functionality
2025-08-17 17:15:48,600 - kivy - WARNING - logger.py:390 - stderr: ----------------------------------------------------------------------
2025-08-17 17:15:48,600 - kivy - WARNING - logger.py:390 - stderr: Traceback (most recent call last):
2025-08-17 17:15:48,600 - kivy - WARNING - logger.py:390 - stderr:   File "/Users/parthchhabra/Desktop/StosOSRpi/stosos/test_task_manager_simple.py", line 295, in test_sorting
2025-08-17 17:15:48,600 - kivy - WARNING - logger.py:390 - stderr:     self.assertTrue(self.task_manager.filtered_tasks[0].is_overdue())
2025-08-17 17:15:48,600 - kivy - WARNING - logger.py:390 - stderr:     ~~~~~~~~~~~~~~~^^^^^^^^^^^^^^^^^^^^^^^^^^^^^^^^^^^^^^^^^^^^^^^^^^
2025-08-17 17:15:48,600 - kivy - WARNING - logger.py:390 - stderr: AssertionError: False is not true
2025-08-17 17:15:48,600 - kivy - WARNING - logger.py:390 - stderr: 
2025-08-17 17:15:48,600 - kivy - WARNING - logger.py:390 - stderr: ======================================================================
2025-08-17 17:15:48,600 - kivy - WARNING - logger.py:390 - stderr: FAIL: test_statistics (__main__.TestTaskManagerCore.test_statistics)
2025-08-17 17:15:48,600 - kivy - WARNING - logger.py:390 - stderr: Test statistics calculation
2025-08-17 17:15:48,600 - kivy - WARNING - logger.py:390 - stderr: ----------------------------------------------------------------------
2025-08-17 17:15:48,600 - kivy - WARNING - logger.py:390 - stderr: Traceback (most recent call last):
2025-08-17 17:15:48,600 - kivy - WARNING - logger.py:390 - stderr:   File "/Users/parthchhabra/Desktop/StosOSRpi/stosos/test_task_manager_simple.py", line 368, in test_statistics
2025-08-17 17:15:48,600 - kivy - WARNING - logger.py:390 - stderr:     self.assertEqual(stats["overdue_tasks"], 1)
2025-08-17 17:15:48,600 - kivy - WARNING - logger.py:390 - stderr:     ~~~~~~~~~~~~~~~~^^^^^^^^^^^^^^^^^^^^^^^^^^^
2025-08-17 17:15:48,600 - kivy - WARNING - logger.py:390 - stderr: AssertionError: 0 != 1
2025-08-17 17:15:48,600 - kivy - WARNING - logger.py:390 - stderr: 
2025-08-17 17:15:48,600 - kivy - WARNING - logger.py:390 - stderr: ----------------------------------------------------------------------
2025-08-17 17:15:48,601 - kivy - WARNING - logger.py:390 - stderr: Ran 15 tests in 0.007s
2025-08-17 17:15:48,601 - kivy - WARNING - logger.py:390 - stderr: 
2025-08-17 17:15:48,601 - kivy - WARNING - logger.py:390 - stderr: FAILED (failures=2)
2025-08-17 17:15:56,144 - core.power_manager - WARNING - power_manager.py:439 - No brightness control method detected
2025-08-17 17:15:56,144 - core.power_manager - INFO - power_manager.py:86 - PowerManager initialized
2025-08-17 17:15:56,148 - kivy - WARNING - logger.py:390 - stderr: test_sorting (test_task_manager_simple.TestTaskManagerCore.test_sorting)
2025-08-17 17:15:56,149 - kivy - WARNING - logger.py:390 - stderr: Test task sorting functionality ... FAIL
2025-08-17 17:15:56,149 - kivy - WARNING - logger.py:390 - stderr: 
2025-08-17 17:15:56,149 - kivy - WARNING - logger.py:390 - stderr: ======================================================================
2025-08-17 17:15:56,149 - kivy - WARNING - logger.py:390 - stderr: FAIL: test_sorting (test_task_manager_simple.TestTaskManagerCore.test_sorting)
2025-08-17 17:15:56,149 - kivy - WARNING - logger.py:390 - stderr: Test task sorting functionality
2025-08-17 17:15:56,149 - kivy - WARNING - logger.py:390 - stderr: ----------------------------------------------------------------------
2025-08-17 17:15:56,149 - kivy - WARNING - logger.py:390 - stderr: Traceback (most recent call last):
2025-08-17 17:15:56,149 - kivy - WARNING - logger.py:390 - stderr:   File "/Users/parthchhabra/Desktop/StosOSRpi/stosos/test_task_manager_simple.py", line 295, in test_sorting
2025-08-17 17:15:56,149 - kivy - WARNING - logger.py:390 - stderr:     self.assertTrue(self.task_manager.filtered_tasks[0].is_overdue())
2025-08-17 17:15:56,149 - kivy - WARNING - logger.py:390 - stderr:     ~~~~~~~~~~~~~~~^^^^^^^^^^^^^^^^^^^^^^^^^^^^^^^^^^^^^^^^^^^^^^^^^^
2025-08-17 17:15:56,149 - kivy - WARNING - logger.py:390 - stderr: AssertionError: False is not true
2025-08-17 17:15:56,149 - kivy - WARNING - logger.py:390 - stderr: 
2025-08-17 17:15:56,149 - kivy - WARNING - logger.py:390 - stderr: ----------------------------------------------------------------------
2025-08-17 17:15:56,149 - kivy - WARNING - logger.py:390 - stderr: Ran 1 test in 0.001s
2025-08-17 17:15:56,149 - kivy - WARNING - logger.py:390 - stderr: 
2025-08-17 17:15:56,149 - kivy - WARNING - logger.py:390 - stderr: FAILED (failures=1)
2025-08-17 17:17:30,105 - core.power_manager - WARNING - power_manager.py:439 - No brightness control method detected
2025-08-17 17:17:30,107 - core.power_manager - INFO - power_manager.py:86 - PowerManager initialized
2025-08-17 17:26:31,434 - core.power_manager - WARNING - power_manager.py:439 - No brightness control method detected
2025-08-17 17:26:31,437 - core.power_manager - INFO - power_manager.py:86 - PowerManager initialized
2025-08-17 17:27:01,974 - core.power_manager - WARNING - power_manager.py:439 - No brightness control method detected
2025-08-17 17:27:01,975 - core.power_manager - INFO - power_manager.py:86 - PowerManager initialized
2025-08-17 17:27:26,338 - core.power_manager - WARNING - power_manager.py:439 - No brightness control method detected
2025-08-17 17:27:26,338 - core.power_manager - INFO - power_manager.py:86 - PowerManager initialized
2025-08-17 17:28:23,189 - core.power_manager - WARNING - power_manager.py:439 - No brightness control method detected
2025-08-17 17:28:23,189 - core.power_manager - INFO - power_manager.py:86 - PowerManager initialized
2025-08-17 17:29:47,134 - core.power_manager - WARNING - power_manager.py:439 - No brightness control method detected
2025-08-17 17:29:47,135 - core.power_manager - INFO - power_manager.py:86 - PowerManager initialized
2025-08-17 17:30:35,798 - core.power_manager - WARNING - power_manager.py:439 - No brightness control method detected
2025-08-17 17:30:35,799 - core.power_manager - INFO - power_manager.py:86 - PowerManager initialized
2025-08-17 17:36:40,872 - core.power_manager - WARNING - power_manager.py:439 - No brightness control method detected
2025-08-17 17:36:40,874 - core.power_manager - INFO - power_manager.py:86 - PowerManager initialized
2025-08-17 17:36:40,886 - kivy - WARNING - logger.py:390 - stderr: Traceback (most recent call last):
2025-08-17 17:36:40,887 - kivy - WARNING - logger.py:390 - stderr:   File "/Users/parthchhabra/Desktop/StosOSRpi/stosos/test_idea_board_simple.py", line 235, in run_all_tests
2025-08-17 17:36:40,887 - kivy - WARNING - logger.py:390 - stderr:     test_idea_model()
2025-08-17 17:36:40,887 - kivy - WARNING - logger.py:390 - stderr:     ~~~~~~~~~~~~~~~^^
2025-08-17 17:36:40,887 - kivy - WARNING - logger.py:390 - stderr:   File "/Users/parthchhabra/Desktop/StosOSRpi/stosos/test_idea_board_simple.py", line 61, in test_idea_model
2025-08-17 17:36:40,887 - kivy - WARNING - logger.py:390 - stderr:     assert restored_idea.tags == idea.tags
2025-08-17 17:36:40,887 - kivy - WARNING - logger.py:390 - stderr:            ^^^^^^^^^^^^^^^^^^^^^^^^^^^^^^^
2025-08-17 17:36:40,887 - kivy - WARNING - logger.py:390 - stderr: AssertionError
2025-08-17 17:41:00,509 - core.power_manager - WARNING - power_manager.py:439 - No brightness control method detected
2025-08-17 17:41:00,510 - core.power_manager - INFO - power_manager.py:86 - PowerManager initialized
2025-08-17 17:41:55,139 - core.power_manager - WARNING - power_manager.py:439 - No brightness control method detected
2025-08-17 17:41:55,141 - core.power_manager - INFO - power_manager.py:86 - PowerManager initialized
2025-08-17 17:43:20,268 - core.power_manager - WARNING - power_manager.py:439 - No brightness control method detected
2025-08-17 17:43:20,270 - core.power_manager - INFO - power_manager.py:86 - PowerManager initialized
2025-08-17 17:43:20,350 - kivy - WARNING - logger.py:390 - stderr: Traceback (most recent call last):
2025-08-17 17:43:20,351 - kivy - WARNING - logger.py:390 - stderr:   File "/Users/parthchhabra/Desktop/StosOSRpi/stosos/verify_idea_board.py", line 117, in verify_database_integration
2025-08-17 17:43:20,351 - kivy - WARNING - logger.py:390 - stderr:     assert len(ideas) == 1, "Content search failed"
2025-08-17 17:43:20,351 - kivy - WARNING - logger.py:390 - stderr:            ^^^^^^^^^^^^^^^
2025-08-17 17:43:20,351 - kivy - WARNING - logger.py:390 - stderr: AssertionError: Content search failed
2025-08-17 17:44:13,850 - core.power_manager - WARNING - power_manager.py:439 - No brightness control method detected
2025-08-17 17:44:13,852 - core.power_manager - INFO - power_manager.py:86 - PowerManager initialized
2025-08-17 17:44:57,817 - core.power_manager - WARNING - power_manager.py:439 - No brightness control method detected
2025-08-17 17:44:57,819 - core.power_manager - INFO - power_manager.py:86 - PowerManager initialized
2025-08-17 17:55:06,874 - core.power_manager - WARNING - power_manager.py:439 - No brightness control method detected
2025-08-17 17:55:06,876 - core.power_manager - INFO - power_manager.py:86 - PowerManager initialized
2025-08-17 17:55:06,890 - kivy - WARNING - logger.py:390 - stderr: Traceback (most recent call last):
2025-08-17 17:55:06,891 - kivy - WARNING - logger.py:390 - stderr:   File "/Users/parthchhabra/Desktop/StosOSRpi/stosos/test_study_tracker_simple.py", line 18, in <module>
2025-08-17 17:55:06,891 - kivy - WARNING - logger.py:390 - stderr:     from modules.study_tracker import StudyStats, StudyGoal, PomodoroTimer
2025-08-17 17:55:06,891 - kivy - WARNING - logger.py:390 - stderr:   File "/Users/parthchhabra/Desktop/StosOSRpi/stosos/modules/__init__.py", line 3, in <module>
2025-08-17 17:55:06,891 - kivy - WARNING - logger.py:390 - stderr:     from .task_manager import TaskManager
2025-08-17 17:55:06,891 - kivy - WARNING - logger.py:390 - stderr:   File "/Users/parthchhabra/Desktop/StosOSRpi/stosos/modules/task_manager.py", line 25, in <module>
2025-08-17 17:55:06,891 - kivy - WARNING - logger.py:390 - stderr:     from ..core.base_module import BaseModule
2025-08-17 17:55:06,891 - kivy - WARNING - logger.py:390 - stderr: ImportError: attempted relative import beyond top-level package
2025-08-17 17:57:15,185 - core.power_manager - WARNING - power_manager.py:439 - No brightness control method detected
2025-08-17 17:57:15,186 - core.power_manager - INFO - power_manager.py:86 - PowerManager initialized
2025-08-17 17:58:25,364 - core.power_manager - WARNING - power_manager.py:439 - No brightness control method detected
2025-08-17 17:58:25,365 - core.power_manager - INFO - power_manager.py:86 - PowerManager initialized
2025-08-17 17:59:46,471 - core.power_manager - WARNING - power_manager.py:439 - No brightness control method detected
2025-08-17 17:59:46,472 - core.power_manager - INFO - power_manager.py:86 - PowerManager initialized
2025-08-17 17:59:46,487 - kivy - WARNING - logger.py:390 - stderr: test_pomodoro_timer_formatting (__main__.TestStudyTrackerCore.test_pomodoro_timer_formatting)
2025-08-17 17:59:46,492 - kivy - WARNING - logger.py:390 - stderr: Test timer formatting functions ... ok
2025-08-17 17:59:46,492 - kivy - WARNING - logger.py:390 - stderr: test_pomodoro_timer_initialization (__main__.TestStudyTrackerCore.test_pomodoro_timer_initialization)
2025-08-17 17:59:46,493 - kivy - WARNING - logger.py:390 - stderr: Test Pomodoro timer initialization ... ok
2025-08-17 17:59:46,493 - kivy - WARNING - logger.py:390 - stderr: test_pomodoro_timer_session_completion (__main__.TestStudyTrackerCore.test_pomodoro_timer_session_completion)
2025-08-17 17:59:46,494 - kivy - WARNING - logger.py:390 - stderr: Test Pomodoro session completion logic ... FAIL
2025-08-17 17:59:46,494 - kivy - WARNING - logger.py:390 - stderr: test_study_goal_creation (__main__.TestStudyTrackerCore.test_study_goal_creation)
2025-08-17 17:59:46,494 - kivy - WARNING - logger.py:390 - stderr: Test StudyGoal creation and serialization ... ok
2025-08-17 17:59:46,494 - kivy - WARNING - logger.py:390 - stderr: test_study_goal_serialization (__main__.TestStudyTrackerCore.test_study_goal_serialization)
2025-08-17 17:59:46,495 - kivy - WARNING - logger.py:390 - stderr: Test StudyGoal serialization and deserialization ... ok
2025-08-17 17:59:46,495 - kivy - WARNING - logger.py:390 - stderr: test_study_stats_daily (__main__.TestStudyTrackerCore.test_study_stats_daily)
2025-08-17 17:59:46,495 - kivy - WARNING - logger.py:390 - stderr: Test daily statistics calculation ... ok
2025-08-17 17:59:46,495 - kivy - WARNING - logger.py:390 - stderr: test_study_stats_streak (__main__.TestStudyTrackerCore.test_study_stats_streak)
2025-08-17 17:59:46,496 - kivy - WARNING - logger.py:390 - stderr: Test study streak calculation ... ok
2025-08-17 17:59:46,496 - kivy - WARNING - logger.py:390 - stderr: test_study_stats_subject_progress (__main__.TestStudyTrackerCore.test_study_stats_subject_progress)
2025-08-17 17:59:46,496 - kivy - WARNING - logger.py:390 - stderr: Test subject-specific progress calculation ... ok
2025-08-17 17:59:46,496 - kivy - WARNING - logger.py:390 - stderr: test_study_stats_weekly (__main__.TestStudyTrackerCore.test_study_stats_weekly)
2025-08-17 17:59:46,497 - kivy - WARNING - logger.py:390 - stderr: Test weekly statistics calculation ... ok
2025-08-17 17:59:46,497 - kivy - WARNING - logger.py:390 - stderr: test_study_session_creation (__main__.TestStudySessionModel.test_study_session_creation)
2025-08-17 17:59:46,497 - kivy - WARNING - logger.py:390 - stderr: Test StudySession creation ... ok
2025-08-17 17:59:46,497 - kivy - WARNING - logger.py:390 - stderr: test_study_session_duration (__main__.TestStudySessionModel.test_study_session_duration)
2025-08-17 17:59:46,497 - kivy - WARNING - logger.py:390 - stderr: Test duration calculation ... ok
2025-08-17 17:59:46,497 - kivy - WARNING - logger.py:390 - stderr: test_study_session_end (__main__.TestStudySessionModel.test_study_session_end)
2025-08-17 17:59:46,497 - kivy - WARNING - logger.py:390 - stderr: Test ending a study session ... ok
2025-08-17 17:59:46,497 - kivy - WARNING - logger.py:390 - stderr: test_study_session_formatting (__main__.TestStudySessionModel.test_study_session_formatting)
2025-08-17 17:59:46,497 - kivy - WARNING - logger.py:390 - stderr: Test formatted duration output ... ok
2025-08-17 17:59:46,497 - kivy - WARNING - logger.py:390 - stderr: test_study_session_serialization (__main__.TestStudySessionModel.test_study_session_serialization)
2025-08-17 17:59:46,497 - kivy - WARNING - logger.py:390 - stderr: Test StudySession serialization ... ok
2025-08-17 17:59:46,497 - kivy - WARNING - logger.py:390 - stderr: test_study_session_tasks (__main__.TestStudySessionModel.test_study_session_tasks)
2025-08-17 17:59:46,497 - kivy - WARNING - logger.py:390 - stderr: Test task completion tracking ... ok
2025-08-17 17:59:46,497 - kivy - WARNING - logger.py:390 - stderr: test_study_session_validation (__main__.TestStudySessionModel.test_study_session_validation)
2025-08-17 17:59:46,497 - kivy - WARNING - logger.py:390 - stderr: Test StudySession validation ... ok
2025-08-17 17:59:46,497 - kivy - WARNING - logger.py:390 - stderr: test_create_study_session (__main__.TestDatabaseIntegration.test_create_study_session)
2025-08-17 17:59:46,500 - kivy - WARNING - logger.py:390 - stderr: Test creating study session in database ... ok
2025-08-17 17:59:46,500 - kivy - WARNING - logger.py:390 - stderr: test_delete_study_session (__main__.TestDatabaseIntegration.test_delete_study_session)
2025-08-17 17:59:46,501 - kivy - WARNING - logger.py:390 - stderr: Test deleting study session from database ... ok
2025-08-17 17:59:46,502 - kivy - WARNING - logger.py:390 - stderr: test_get_study_session (__main__.TestDatabaseIntegration.test_get_study_session)
2025-08-17 17:59:46,503 - kivy - WARNING - logger.py:390 - stderr: Test retrieving study session from database ... ok
2025-08-17 17:59:46,503 - kivy - WARNING - logger.py:390 - stderr: test_get_study_sessions_filtering (__main__.TestDatabaseIntegration.test_get_study_sessions_filtering)
2025-08-17 17:59:46,507 - kivy - WARNING - logger.py:390 - stderr: Test filtering study sessions ... ok
2025-08-17 17:59:46,507 - kivy - WARNING - logger.py:390 - stderr: test_update_study_session (__main__.TestDatabaseIntegration.test_update_study_session)
2025-08-17 17:59:46,508 - kivy - WARNING - logger.py:390 - stderr: Test updating study session in database ... ok
2025-08-17 17:59:46,508 - kivy - WARNING - logger.py:390 - stderr: 
2025-08-17 17:59:46,508 - kivy - WARNING - logger.py:390 - stderr: ======================================================================
2025-08-17 17:59:46,508 - kivy - WARNING - logger.py:390 - stderr: FAIL: test_pomodoro_timer_session_completion (__main__.TestStudyTrackerCore.test_pomodoro_timer_session_completion)
2025-08-17 17:59:46,508 - kivy - WARNING - logger.py:390 - stderr: Test Pomodoro session completion logic
2025-08-17 17:59:46,508 - kivy - WARNING - logger.py:390 - stderr: ----------------------------------------------------------------------
2025-08-17 17:59:46,508 - kivy - WARNING - logger.py:390 - stderr: Traceback (most recent call last):
2025-08-17 17:59:46,508 - kivy - WARNING - logger.py:390 - stderr:   File "/Users/parthchhabra/Desktop/StosOSRpi/stosos/test_study_tracker.py", line 88, in test_pomodoro_timer_session_completion
2025-08-17 17:59:46,508 - kivy - WARNING - logger.py:390 - stderr:     self.assertEqual(timer.current_time, timer.long_break_duration)
2025-08-17 17:59:46,508 - kivy - WARNING - logger.py:390 - stderr:     ~~~~~~~~~~~~~~~~^^^^^^^^^^^^^^^^^^^^^^^^^^^^^^^^^^^^^^^^^^^^^^^
2025-08-17 17:59:46,508 - kivy - WARNING - logger.py:390 - stderr: AssertionError: 300 != 900
2025-08-17 17:59:46,508 - kivy - WARNING - logger.py:390 - stderr: 
2025-08-17 17:59:46,508 - kivy - WARNING - logger.py:390 - stderr: ----------------------------------------------------------------------
2025-08-17 17:59:46,508 - kivy - WARNING - logger.py:390 - stderr: Ran 21 tests in 0.021s
2025-08-17 17:59:46,508 - kivy - WARNING - logger.py:390 - stderr: 
2025-08-17 17:59:46,508 - kivy - WARNING - logger.py:390 - stderr: FAILED (failures=1)
2025-08-17 17:59:56,654 - core.power_manager - WARNING - power_manager.py:439 - No brightness control method detected
2025-08-17 17:59:56,654 - core.power_manager - INFO - power_manager.py:86 - PowerManager initialized
2025-08-17 17:59:56,667 - kivy - WARNING - logger.py:390 - stderr: test_create_study_session (test_study_tracker.TestDatabaseIntegration.test_create_study_session)
2025-08-17 17:59:56,675 - kivy - WARNING - logger.py:390 - stderr: Test creating study session in database ... ok
2025-08-17 17:59:56,675 - kivy - WARNING - logger.py:390 - stderr: test_delete_study_session (test_study_tracker.TestDatabaseIntegration.test_delete_study_session)
2025-08-17 17:59:56,679 - kivy - WARNING - logger.py:390 - stderr: Test deleting study session from database ... /Users/parthchhabra/Desktop/StosOSRpi/stosos/core/database_manager.py:75: ResourceWarning: unclosed database in <sqlite3.Connection object at 0x10b21b3d0>
2025-08-17 17:59:56,679 - kivy - WARNING - logger.py:390 - stderr:   cursor = conn.cursor()
2025-08-17 17:59:56,679 - kivy - WARNING - logger.py:390 - stderr: ResourceWarning: Enable tracemalloc to get the object allocation traceback
2025-08-17 17:59:56,680 - kivy - WARNING - logger.py:390 - stderr: ok
2025-08-17 17:59:56,680 - kivy - WARNING - logger.py:390 - stderr: test_get_study_session (test_study_tracker.TestDatabaseIntegration.test_get_study_session)
2025-08-17 17:59:56,681 - kivy - WARNING - logger.py:390 - stderr: Test retrieving study session from database ... ok
2025-08-17 17:59:56,681 - kivy - WARNING - logger.py:390 - stderr: test_get_study_sessions_filtering (test_study_tracker.TestDatabaseIntegration.test_get_study_sessions_filtering)
2025-08-17 17:59:56,684 - kivy - WARNING - logger.py:390 - stderr: Test filtering study sessions ... ok
2025-08-17 17:59:56,684 - kivy - WARNING - logger.py:390 - stderr: test_update_study_session (test_study_tracker.TestDatabaseIntegration.test_update_study_session)
2025-08-17 17:59:56,685 - kivy - WARNING - logger.py:390 - stderr: Test updating study session in database ... ok
2025-08-17 17:59:56,685 - kivy - WARNING - logger.py:390 - stderr: test_study_session_creation (test_study_tracker.TestStudySessionModel.test_study_session_creation)
2025-08-17 17:59:56,685 - kivy - WARNING - logger.py:390 - stderr: Test StudySession creation ... ok
2025-08-17 17:59:56,685 - kivy - WARNING - logger.py:390 - stderr: test_study_session_duration (test_study_tracker.TestStudySessionModel.test_study_session_duration)
2025-08-17 17:59:56,685 - kivy - WARNING - logger.py:390 - stderr: Test duration calculation ... ok
2025-08-17 17:59:56,685 - kivy - WARNING - logger.py:390 - stderr: test_study_session_end (test_study_tracker.TestStudySessionModel.test_study_session_end)
2025-08-17 17:59:56,685 - kivy - WARNING - logger.py:390 - stderr: Test ending a study session ... ok
2025-08-17 17:59:56,685 - kivy - WARNING - logger.py:390 - stderr: test_study_session_formatting (test_study_tracker.TestStudySessionModel.test_study_session_formatting)
2025-08-17 17:59:56,686 - kivy - WARNING - logger.py:390 - stderr: Test formatted duration output ... ok
2025-08-17 17:59:56,686 - kivy - WARNING - logger.py:390 - stderr: test_study_session_serialization (test_study_tracker.TestStudySessionModel.test_study_session_serialization)
2025-08-17 17:59:56,686 - kivy - WARNING - logger.py:390 - stderr: Test StudySession serialization ... ok
2025-08-17 17:59:56,686 - kivy - WARNING - logger.py:390 - stderr: test_study_session_tasks (test_study_tracker.TestStudySessionModel.test_study_session_tasks)
2025-08-17 17:59:56,686 - kivy - WARNING - logger.py:390 - stderr: Test task completion tracking ... ok
2025-08-17 17:59:56,686 - kivy - WARNING - logger.py:390 - stderr: test_study_session_validation (test_study_tracker.TestStudySessionModel.test_study_session_validation)
2025-08-17 17:59:56,686 - kivy - WARNING - logger.py:390 - stderr: Test StudySession validation ... ok
2025-08-17 17:59:56,686 - kivy - WARNING - logger.py:390 - stderr: test_pomodoro_timer_formatting (test_study_tracker.TestStudyTrackerCore.test_pomodoro_timer_formatting)
2025-08-17 17:59:56,687 - kivy - WARNING - logger.py:390 - stderr: Test timer formatting functions ... ok
2025-08-17 17:59:56,687 - kivy - WARNING - logger.py:390 - stderr: test_pomodoro_timer_initialization (test_study_tracker.TestStudyTrackerCore.test_pomodoro_timer_initialization)
2025-08-17 17:59:56,688 - kivy - WARNING - logger.py:390 - stderr: Test Pomodoro timer initialization ... ok
2025-08-17 17:59:56,688 - kivy - WARNING - logger.py:390 - stderr: test_pomodoro_timer_session_completion (test_study_tracker.TestStudyTrackerCore.test_pomodoro_timer_session_completion)
2025-08-17 17:59:56,688 - kivy - WARNING - logger.py:390 - stderr: Test Pomodoro session completion logic ... FAIL
2025-08-17 17:59:56,688 - kivy - WARNING - logger.py:390 - stderr: test_study_goal_creation (test_study_tracker.TestStudyTrackerCore.test_study_goal_creation)
2025-08-17 17:59:56,689 - kivy - WARNING - logger.py:390 - stderr: Test StudyGoal creation and serialization ... ok
2025-08-17 17:59:56,689 - kivy - WARNING - logger.py:390 - stderr: test_study_goal_serialization (test_study_tracker.TestStudyTrackerCore.test_study_goal_serialization)
2025-08-17 17:59:56,689 - kivy - WARNING - logger.py:390 - stderr: Test StudyGoal serialization and deserialization ... ok
2025-08-17 17:59:56,689 - kivy - WARNING - logger.py:390 - stderr: test_study_stats_daily (test_study_tracker.TestStudyTrackerCore.test_study_stats_daily)
2025-08-17 17:59:56,690 - kivy - WARNING - logger.py:390 - stderr: Test daily statistics calculation ... ok
2025-08-17 17:59:56,690 - kivy - WARNING - logger.py:390 - stderr: test_study_stats_streak (test_study_tracker.TestStudyTrackerCore.test_study_stats_streak)
2025-08-17 17:59:56,690 - kivy - WARNING - logger.py:390 - stderr: Test study streak calculation ... ok
2025-08-17 17:59:56,690 - kivy - WARNING - logger.py:390 - stderr: test_study_stats_subject_progress (test_study_tracker.TestStudyTrackerCore.test_study_stats_subject_progress)
2025-08-17 17:59:56,690 - kivy - WARNING - logger.py:390 - stderr: Test subject-specific progress calculation ... ok
2025-08-17 17:59:56,690 - kivy - WARNING - logger.py:390 - stderr: test_study_stats_weekly (test_study_tracker.TestStudyTrackerCore.test_study_stats_weekly)
2025-08-17 17:59:56,691 - kivy - WARNING - logger.py:390 - stderr: Test weekly statistics calculation ... ok
2025-08-17 17:59:56,691 - kivy - WARNING - logger.py:390 - stderr: 
2025-08-17 17:59:56,691 - kivy - WARNING - logger.py:390 - stderr: ======================================================================
2025-08-17 17:59:56,691 - kivy - WARNING - logger.py:390 - stderr: FAIL: test_pomodoro_timer_session_completion (test_study_tracker.TestStudyTrackerCore.test_pomodoro_timer_session_completion)
2025-08-17 17:59:56,691 - kivy - WARNING - logger.py:390 - stderr: Test Pomodoro session completion logic
2025-08-17 17:59:56,691 - kivy - WARNING - logger.py:390 - stderr: ----------------------------------------------------------------------
2025-08-17 17:59:56,691 - kivy - WARNING - logger.py:390 - stderr: Traceback (most recent call last):
2025-08-17 17:59:56,691 - kivy - WARNING - logger.py:390 - stderr:   File "/Users/parthchhabra/Desktop/StosOSRpi/stosos/test_study_tracker.py", line 88, in test_pomodoro_timer_session_completion
2025-08-17 17:59:56,691 - kivy - WARNING - logger.py:390 - stderr:     self.assertEqual(timer.current_time, timer.long_break_duration)
2025-08-17 17:59:56,691 - kivy - WARNING - logger.py:390 - stderr:     ~~~~~~~~~~~~~~~~^^^^^^^^^^^^^^^^^^^^^^^^^^^^^^^^^^^^^^^^^^^^^^^
2025-08-17 17:59:56,691 - kivy - WARNING - logger.py:390 - stderr: AssertionError: 300 != 900
2025-08-17 17:59:56,692 - kivy - WARNING - logger.py:390 - stderr: 
2025-08-17 17:59:56,692 - kivy - WARNING - logger.py:390 - stderr: ----------------------------------------------------------------------
2025-08-17 17:59:56,692 - kivy - WARNING - logger.py:390 - stderr: Ran 21 tests in 0.024s
2025-08-17 17:59:56,692 - kivy - WARNING - logger.py:390 - stderr: 
2025-08-17 17:59:56,692 - kivy - WARNING - logger.py:390 - stderr: FAILED (failures=1)
2025-08-17 18:00:10,530 - core.power_manager - WARNING - power_manager.py:439 - No brightness control method detected
2025-08-17 18:00:10,530 - core.power_manager - INFO - power_manager.py:86 - PowerManager initialized
2025-08-17 18:26:47,509 - core.power_manager - WARNING - power_manager.py:439 - No brightness control method detected
2025-08-17 18:26:47,511 - core.power_manager - INFO - power_manager.py:86 - PowerManager initialized
2025-08-17 18:26:47,515 - kivy - WARNING - logger.py:390 - stderr: Traceback (most recent call last):
2025-08-17 18:26:47,515 - kivy - WARNING - logger.py:390 - stderr:   File "/Users/parthchhabra/Desktop/StosOSRpi/stosos/test_dashboard.py", line 25, in <module>
2025-08-17 18:26:47,516 - kivy - WARNING - logger.py:390 - stderr:     from modules.dashboard import DashboardModule
2025-08-17 18:26:47,516 - kivy - WARNING - logger.py:390 - stderr:   File "/Users/parthchhabra/Desktop/StosOSRpi/stosos/modules/__init__.py", line 3, in <module>
2025-08-17 18:26:47,516 - kivy - WARNING - logger.py:390 - stderr:     from .task_manager import TaskManager
2025-08-17 18:26:47,516 - kivy - WARNING - logger.py:390 - stderr:   File "/Users/parthchhabra/Desktop/StosOSRpi/stosos/modules/task_manager.py", line 25, in <module>
2025-08-17 18:26:47,516 - kivy - WARNING - logger.py:390 - stderr:     from ..core.base_module import BaseModule
2025-08-17 18:26:47,516 - kivy - WARNING - logger.py:390 - stderr: ImportError: attempted relative import beyond top-level package
2025-08-17 18:27:11,506 - core.power_manager - WARNING - power_manager.py:439 - No brightness control method detected
2025-08-17 18:27:11,506 - core.power_manager - INFO - power_manager.py:86 - PowerManager initialized
2025-08-17 18:27:11,510 - kivy - WARNING - logger.py:390 - stderr: Traceback (most recent call last):
2025-08-17 18:27:11,510 - kivy - WARNING - logger.py:390 - stderr:   File "/Users/parthchhabra/Desktop/StosOSRpi/stosos/test_dashboard_simple.py", line 27, in test_dashboard_import
2025-08-17 18:27:11,510 - kivy - WARNING - logger.py:390 - stderr:     from modules.dashboard import DashboardModule
2025-08-17 18:27:11,510 - kivy - WARNING - logger.py:390 - stderr:   File "/Users/parthchhabra/Desktop/StosOSRpi/stosos/modules/__init__.py", line 3, in <module>
2025-08-17 18:27:11,510 - kivy - WARNING - logger.py:390 - stderr:     from .task_manager import TaskManager
2025-08-17 18:27:11,510 - kivy - WARNING - logger.py:390 - stderr:   File "/Users/parthchhabra/Desktop/StosOSRpi/stosos/modules/task_manager.py", line 25, in <module>
2025-08-17 18:27:11,510 - kivy - WARNING - logger.py:390 - stderr:     from ..core.base_module import BaseModule
2025-08-17 18:27:11,510 - kivy - WARNING - logger.py:390 - stderr: ImportError: attempted relative import beyond top-level package
2025-08-17 18:27:11,511 - kivy - WARNING - logger.py:390 - stderr: Traceback (most recent call last):
2025-08-17 18:27:11,511 - kivy - WARNING - logger.py:390 - stderr:   File "/Users/parthchhabra/Desktop/StosOSRpi/stosos/test_dashboard_simple.py", line 55, in test_dashboard_initialization
2025-08-17 18:27:11,511 - kivy - WARNING - logger.py:390 - stderr:     from modules.dashboard import DashboardModule
2025-08-17 18:27:11,511 - kivy - WARNING - logger.py:390 - stderr:   File "/Users/parthchhabra/Desktop/StosOSRpi/stosos/modules/__init__.py", line 3, in <module>
2025-08-17 18:27:11,511 - kivy - WARNING - logger.py:390 - stderr:     from .task_manager import TaskManager
2025-08-17 18:27:11,511 - kivy - WARNING - logger.py:390 - stderr:   File "/Users/parthchhabra/Desktop/StosOSRpi/stosos/modules/task_manager.py", line 25, in <module>
2025-08-17 18:27:11,511 - kivy - WARNING - logger.py:390 - stderr:     from ..core.base_module import BaseModule
2025-08-17 18:27:11,511 - kivy - WARNING - logger.py:390 - stderr: ImportError: attempted relative import beyond top-level package
2025-08-17 18:27:31,288 - core.power_manager - WARNING - power_manager.py:439 - No brightness control method detected
2025-08-17 18:27:31,289 - core.power_manager - INFO - power_manager.py:86 - PowerManager initialized
2025-08-17 18:27:31,292 - kivy - WARNING - logger.py:390 - stderr: Traceback (most recent call last):
2025-08-17 18:27:31,293 - kivy - WARNING - logger.py:390 - stderr:   File "/Users/parthchhabra/Desktop/StosOSRpi/stosos/test_dashboard_simple.py", line 27, in test_dashboard_import
2025-08-17 18:27:31,293 - kivy - WARNING - logger.py:390 - stderr:     from modules.dashboard import DashboardModule
2025-08-17 18:27:31,293 - kivy - WARNING - logger.py:390 - stderr:   File "/Users/parthchhabra/Desktop/StosOSRpi/stosos/modules/__init__.py", line 3, in <module>
2025-08-17 18:27:31,293 - kivy - WARNING - logger.py:390 - stderr:     from .task_manager import TaskManager
2025-08-17 18:27:31,293 - kivy - WARNING - logger.py:390 - stderr:   File "/Users/parthchhabra/Desktop/StosOSRpi/stosos/modules/task_manager.py", line 25, in <module>
2025-08-17 18:27:31,293 - kivy - WARNING - logger.py:390 - stderr:     from ..core.base_module import BaseModule
2025-08-17 18:27:31,293 - kivy - WARNING - logger.py:390 - stderr: ImportError: attempted relative import beyond top-level package
2025-08-17 18:27:31,293 - kivy - WARNING - logger.py:390 - stderr: Traceback (most recent call last):
2025-08-17 18:27:31,293 - kivy - WARNING - logger.py:390 - stderr:   File "/Users/parthchhabra/Desktop/StosOSRpi/stosos/test_dashboard_simple.py", line 55, in test_dashboard_initialization
2025-08-17 18:27:31,293 - kivy - WARNING - logger.py:390 - stderr:     from modules.dashboard import DashboardModule
2025-08-17 18:27:31,293 - kivy - WARNING - logger.py:390 - stderr:   File "/Users/parthchhabra/Desktop/StosOSRpi/stosos/modules/__init__.py", line 3, in <module>
2025-08-17 18:27:31,293 - kivy - WARNING - logger.py:390 - stderr:     from .task_manager import TaskManager
2025-08-17 18:27:31,293 - kivy - WARNING - logger.py:390 - stderr:   File "/Users/parthchhabra/Desktop/StosOSRpi/stosos/modules/task_manager.py", line 25, in <module>
2025-08-17 18:27:31,293 - kivy - WARNING - logger.py:390 - stderr:     from ..core.base_module import BaseModule
2025-08-17 18:27:31,293 - kivy - WARNING - logger.py:390 - stderr: ImportError: attempted relative import beyond top-level package
2025-08-17 18:27:57,849 - core.power_manager - WARNING - power_manager.py:439 - No brightness control method detected
2025-08-17 18:27:57,850 - core.power_manager - INFO - power_manager.py:86 - PowerManager initialized
2025-08-17 18:27:57,854 - kivy - WARNING - logger.py:390 - stderr: Traceback (most recent call last):
2025-08-17 18:27:57,854 - kivy - WARNING - logger.py:390 - stderr:   File "/Users/parthchhabra/Desktop/StosOSRpi/stosos/test_dashboard_simple.py", line 27, in test_dashboard_import
2025-08-17 18:27:57,854 - kivy - WARNING - logger.py:390 - stderr:     from modules.dashboard import DashboardModule
2025-08-17 18:27:57,854 - kivy - WARNING - logger.py:390 - stderr:   File "/Users/parthchhabra/Desktop/StosOSRpi/stosos/modules/__init__.py", line 3, in <module>
2025-08-17 18:27:57,854 - kivy - WARNING - logger.py:390 - stderr:     from .task_manager import TaskManager
2025-08-17 18:27:57,854 - kivy - WARNING - logger.py:390 - stderr:   File "/Users/parthchhabra/Desktop/StosOSRpi/stosos/modules/task_manager.py", line 25, in <module>
2025-08-17 18:27:57,854 - kivy - WARNING - logger.py:390 - stderr:     from ..core.base_module import BaseModule
2025-08-17 18:27:57,854 - kivy - WARNING - logger.py:390 - stderr: ImportError: attempted relative import beyond top-level package
2025-08-17 18:27:57,855 - kivy - WARNING - logger.py:390 - stderr: Traceback (most recent call last):
2025-08-17 18:27:57,855 - kivy - WARNING - logger.py:390 - stderr:   File "/Users/parthchhabra/Desktop/StosOSRpi/stosos/test_dashboard_simple.py", line 55, in test_dashboard_initialization
2025-08-17 18:27:57,855 - kivy - WARNING - logger.py:390 - stderr:     from modules.dashboard import DashboardModule
2025-08-17 18:27:57,855 - kivy - WARNING - logger.py:390 - stderr:   File "/Users/parthchhabra/Desktop/StosOSRpi/stosos/modules/__init__.py", line 3, in <module>
2025-08-17 18:27:57,855 - kivy - WARNING - logger.py:390 - stderr:     from .task_manager import TaskManager
2025-08-17 18:27:57,855 - kivy - WARNING - logger.py:390 - stderr:   File "/Users/parthchhabra/Desktop/StosOSRpi/stosos/modules/task_manager.py", line 25, in <module>
2025-08-17 18:27:57,855 - kivy - WARNING - logger.py:390 - stderr:     from ..core.base_module import BaseModule
2025-08-17 18:27:57,855 - kivy - WARNING - logger.py:390 - stderr: ImportError: attempted relative import beyond top-level package
2025-08-17 18:30:18,400 - core.power_manager - WARNING - power_manager.py:439 - No brightness control method detected
2025-08-17 18:30:18,404 - core.power_manager - INFO - power_manager.py:86 - PowerManager initialized
2025-08-17 18:30:19,815 - kivy - WARNING - logger.py:390 - stderr: Traceback (most recent call last):
2025-08-17 18:30:19,819 - kivy - WARNING - logger.py:390 - stderr:   File "/Users/parthchhabra/Desktop/StosOSRpi/stosos/test_dashboard_simple.py", line 31, in test_dashboard_import
2025-08-17 18:30:19,819 - kivy - WARNING - logger.py:390 - stderr:     dashboard = DashboardModule()
2025-08-17 18:30:19,819 - kivy - WARNING - logger.py:390 - stderr:   File "/Users/parthchhabra/Desktop/StosOSRpi/stosos/modules/dashboard.py", line 603, in __init__
2025-08-17 18:30:19,819 - kivy - WARNING - logger.py:390 - stderr:     super().__init__(
2025-08-17 18:30:19,819 - kivy - WARNING - logger.py:390 - stderr:     ~~~~~~~~~~~~~~~~^
2025-08-17 18:30:19,819 - kivy - WARNING - logger.py:390 - stderr:         module_id="dashboard",
2025-08-17 18:30:19,819 - kivy - WARNING - logger.py:390 - stderr:         ^^^^^^^^^^^^^^^^^^^^^^
2025-08-17 18:30:19,819 - kivy - WARNING - logger.py:390 - stderr:     ...<2 lines>...
2025-08-17 18:30:19,819 - kivy - WARNING - logger.py:390 - stderr:         icon="🏠"
2025-08-17 18:30:19,819 - kivy - WARNING - logger.py:390 - stderr:         ^^^^^^^^^
2025-08-17 18:30:19,819 - kivy - WARNING - logger.py:390 - stderr:     )
2025-08-17 18:30:19,819 - kivy - WARNING - logger.py:390 - stderr:     ^
2025-08-17 18:30:19,819 - kivy - WARNING - logger.py:390 - stderr: TypeError: BaseModule.__init__() got an unexpected keyword argument 'description'
2025-08-17 18:30:19,820 - core.config_manager - INFO - config_manager.py:30 - Configuration loaded successfully
2025-08-17 18:30:19,820 - kivy - WARNING - logger.py:390 - stderr: Traceback (most recent call last):
2025-08-17 18:30:19,820 - kivy - WARNING - logger.py:390 - stderr:   File "/Users/parthchhabra/Desktop/StosOSRpi/stosos/test_dashboard_simple.py", line 62, in test_dashboard_initialization
2025-08-17 18:30:19,820 - kivy - WARNING - logger.py:390 - stderr:     dashboard = DashboardModule()
2025-08-17 18:30:19,821 - kivy - WARNING - logger.py:390 - stderr:   File "/Users/parthchhabra/Desktop/StosOSRpi/stosos/modules/dashboard.py", line 603, in __init__
2025-08-17 18:30:19,821 - kivy - WARNING - logger.py:390 - stderr:     super().__init__(
2025-08-17 18:30:19,821 - kivy - WARNING - logger.py:390 - stderr:     ~~~~~~~~~~~~~~~~^
2025-08-17 18:30:19,821 - kivy - WARNING - logger.py:390 - stderr:         module_id="dashboard",
2025-08-17 18:30:19,821 - kivy - WARNING - logger.py:390 - stderr:         ^^^^^^^^^^^^^^^^^^^^^^
2025-08-17 18:30:19,821 - kivy - WARNING - logger.py:390 - stderr:     ...<2 lines>...
2025-08-17 18:30:19,821 - kivy - WARNING - logger.py:390 - stderr:         icon="🏠"
2025-08-17 18:30:19,821 - kivy - WARNING - logger.py:390 - stderr:         ^^^^^^^^^
2025-08-17 18:30:19,821 - kivy - WARNING - logger.py:390 - stderr:     )
2025-08-17 18:30:19,821 - kivy - WARNING - logger.py:390 - stderr:     ^
2025-08-17 18:30:19,821 - kivy - WARNING - logger.py:390 - stderr: TypeError: BaseModule.__init__() got an unexpected keyword argument 'description'
2025-08-17 18:30:41,907 - core.power_manager - WARNING - power_manager.py:439 - No brightness control method detected
2025-08-17 18:30:41,907 - core.power_manager - INFO - power_manager.py:86 - PowerManager initialized
2025-08-17 18:30:43,107 - core.config_manager - INFO - config_manager.py:30 - Configuration loaded successfully
2025-08-17 18:30:43,107 - modules.dashboard - INFO - dashboard.py:623 - Initializing Dashboard module
2025-08-17 18:30:43,129 - modules.dashboard - INFO - dashboard.py:631 - Dashboard module initialized successfully
2025-08-17 18:31:14,074 - core.power_manager - WARNING - power_manager.py:439 - No brightness control method detected
2025-08-17 18:31:14,075 - core.power_manager - INFO - power_manager.py:86 - PowerManager initialized
2025-08-17 18:31:15,323 - core.config_manager - INFO - config_manager.py:30 - Configuration loaded successfully
2025-08-17 18:31:15,325 - modules.dashboard - INFO - dashboard.py:623 - Initializing Dashboard module
2025-08-17 18:31:15,345 - modules.dashboard - INFO - dashboard.py:631 - Dashboard module initialized successfully
2025-08-17 18:31:15,345 - modules.dashboard - INFO - dashboard.py:623 - Initializing Dashboard module
2025-08-17 18:31:15,353 - modules.dashboard - INFO - dashboard.py:631 - Dashboard module initialized successfully
2025-08-17 18:31:15,353 - core.screen_manager - INFO - screen_manager.py:65 - Module registered successfully: dashboard
2025-08-17 18:31:15,353 - modules.dashboard - DEBUG - dashboard.py:1040 - Dashboard module deactivated
2025-08-17 18:31:15,354 - modules.dashboard - DEBUG - dashboard.py:1034 - Dashboard module activated
2025-08-17 18:31:15,354 - core.screen_manager - DEBUG - screen_manager.py:157 - Navigated to module: dashboard
2025-08-17 18:31:15,354 - modules.dashboard - INFO - dashboard.py:1058 - Cleaning up Dashboard module
2025-08-17 18:31:15,354 - modules.dashboard - DEBUG - base_module.py:91 - Module dashboard cleaned up
2025-08-17 18:31:58,504 - core.power_manager - WARNING - power_manager.py:439 - No brightness control method detected
2025-08-17 18:31:58,508 - core.power_manager - INFO - power_manager.py:86 - PowerManager initialized
2025-08-17 20:50:43,753 - core.power_manager - WARNING - power_manager.py:439 - No brightness control method detected
2025-08-17 20:50:43,756 - core.power_manager - INFO - power_manager.py:86 - PowerManager initialized
2025-08-17 20:50:43,759 - core.error_handler - WARNING - error_handler.py:292 - Error in test_context: Test error message (Type: module, Module: test_module)
2025-08-17 20:50:43,759 - core.error_handler - INFO - error_handler.py:435 - Attempting to restart module: test_module
2025-08-17 20:50:45,822 - core.module_recovery_manager - INFO - module_recovery_manager.py:72 - Registered module healthy_test for recovery management
2025-08-17 20:50:45,823 - core.module_recovery_manager - INFO - module_recovery_manager.py:72 - Registered module failing_test for recovery management
2025-08-17 20:50:45,823 - core.module_recovery_manager - INFO - module_recovery_manager.py:113 - Restarting module failing_test
2025-08-17 20:50:45,823 - stosos.modules.failing_test - INFO - base_module.py:99 - Restarting module failing_test
2025-08-17 20:50:45,823 - stosos.modules.failing_test - ERROR - base_module.py:117 - Error during module restart: Test module failing_test initialization failed
2025-08-17 20:50:45,824 - core.error_handler - WARNING - error_handler.py:292 - Error in failing_test:module_restart: Test module failing_test initialization failed (Type: module, Module: failing_test)
2025-08-17 20:50:45,824 - core.error_handler - INFO - error_handler.py:435 - Attempting to restart module: failing_test
2025-08-17 20:50:45,824 - core.module_recovery_manager - ERROR - module_recovery_manager.py:138 - Module failing_test restart failed
2025-08-17 20:50:45,824 - core.module_recovery_manager - INFO - module_recovery_manager.py:274 - Fallback mode enabled for module failing_test
2025-08-17 20:50:45,824 - core.module_recovery_manager - INFO - module_recovery_manager.py:88 - Unregistered module healthy_test
2025-08-17 20:50:45,824 - core.module_recovery_manager - INFO - module_recovery_manager.py:88 - Unregistered module failing_test
2025-08-17 20:50:45,824 - core.module_recovery_manager - INFO - module_recovery_manager.py:72 - Registered module integration_test for recovery management
2025-08-17 20:50:45,824 - core.error_handler - WARNING - error_handler.py:292 - Error in integration_test:initialization: Test module integration_test initialization failed (Type: module, Module: integration_test)
2025-08-17 20:50:45,824 - core.error_handler - INFO - error_handler.py:435 - Attempting to restart module: integration_test
2025-08-17 20:50:45,825 - core.module_recovery_manager - INFO - module_recovery_manager.py:88 - Unregistered module integration_test
2025-08-17 20:50:45,825 - core.module_recovery_manager - INFO - module_recovery_manager.py:72 - Registered module degraded_test for recovery management
2025-08-17 20:50:45,825 - core.error_handler - WARNING - error_handler.py:292 - Error in degraded_test:initialization_attempt_0: Test module degraded_test initialization failed (Type: module, Module: degraded_test)
2025-08-17 20:50:45,825 - core.error_handler - INFO - error_handler.py:435 - Attempting to restart module: degraded_test
2025-08-17 20:50:45,825 - core.error_handler - WARNING - error_handler.py:292 - Error in degraded_test:initialization_attempt_1: Test module degraded_test initialization failed (Type: module, Module: degraded_test)
2025-08-17 20:50:45,825 - core.error_handler - INFO - error_handler.py:306 - Attempting recovery for module error
2025-08-17 20:50:45,825 - core.error_handler - INFO - error_handler.py:256 - Attempting module error recovery for context: degraded_test:initialization_attempt_1
2025-08-17 20:50:45,825 - core.error_handler - WARNING - error_handler.py:321 - Error pattern detected: module:Exception occurred 5 times
2025-08-17 20:50:45,825 - core.module_recovery_manager - INFO - module_recovery_manager.py:348 - Automatically restarting failed module degraded_test
2025-08-17 20:50:45,825 - core.module_recovery_manager - INFO - module_recovery_manager.py:113 - Restarting module degraded_test
2025-08-17 20:50:45,825 - stosos.modules.degraded_test - INFO - base_module.py:99 - Restarting module degraded_test
2025-08-17 20:50:45,825 - stosos.modules.degraded_test - INFO - base_module.py:108 - Module degraded_test restarted successfully
2025-08-17 20:50:45,825 - core.module_recovery_manager - INFO - module_recovery_manager.py:128 - Module degraded_test restarted successfully
2025-08-17 20:50:45,825 - core.module_recovery_manager - INFO - module_recovery_manager.py:88 - Unregistered module degraded_test
2025-08-17 20:50:45,825 - core.error_handler - WARNING - error_handler.py:292 - Error in pattern_test: Network error 0 (Type: network, Module: pattern_test_module)
2025-08-17 20:50:45,825 - core.error_handler - INFO - error_handler.py:435 - Attempting to restart module: pattern_test_module
2025-08-17 20:50:45,825 - core.error_handler - WARNING - error_handler.py:292 - Error in pattern_test: Network error 1 (Type: network, Module: pattern_test_module)
2025-08-17 20:50:45,825 - core.error_handler - INFO - error_handler.py:306 - Attempting recovery for network error
2025-08-17 20:50:45,825 - core.error_handler - INFO - error_handler.py:250 - Attempting network error recovery
2025-08-17 20:50:45,826 - core.error_handler - WARNING - error_handler.py:292 - Error in pattern_test: Network error 2 (Type: network, Module: pattern_test_module)
2025-08-17 20:50:45,826 - core.error_handler - INFO - error_handler.py:306 - Attempting recovery for network error
2025-08-17 20:50:45,826 - core.error_handler - INFO - error_handler.py:250 - Attempting network error recovery
2025-08-17 20:50:45,826 - core.error_handler - WARNING - error_handler.py:292 - Error in pattern_test: Network error 3 (Type: network, Module: pattern_test_module)
2025-08-17 20:50:45,826 - core.error_handler - INFO - error_handler.py:306 - Attempting recovery for network error
2025-08-17 20:50:45,826 - core.error_handler - INFO - error_handler.py:250 - Attempting network error recovery
2025-08-17 20:50:45,826 - core.error_handler - WARNING - error_handler.py:292 - Error in pattern_test: Network error 4 (Type: network, Module: pattern_test_module)
2025-08-17 20:50:45,826 - core.error_handler - INFO - error_handler.py:306 - Attempting recovery for network error
2025-08-17 20:50:45,826 - core.error_handler - INFO - error_handler.py:250 - Attempting network error recovery
2025-08-17 20:50:45,826 - core.error_handler - WARNING - error_handler.py:321 - Error pattern detected: network:ConnectionError occurred 5 times
2025-08-17 20:50:45,826 - core.error_handler - WARNING - error_handler.py:292 - Error in pattern_test: Network error 5 (Type: network, Module: pattern_test_module)
2025-08-17 20:50:45,826 - core.error_handler - INFO - error_handler.py:306 - Attempting recovery for network error
2025-08-17 20:50:45,826 - core.error_handler - INFO - error_handler.py:250 - Attempting network error recovery
2025-08-17 20:50:45,826 - core.error_handler - WARNING - error_handler.py:292 - Error in pattern_test: Network error 6 (Type: network, Module: pattern_test_module)
2025-08-17 20:50:45,826 - core.error_handler - INFO - error_handler.py:306 - Attempting recovery for network error
2025-08-17 20:50:45,826 - core.error_handler - INFO - error_handler.py:250 - Attempting network error recovery
2025-08-17 20:50:45,826 - core.error_handler - WARNING - error_handler.py:292 - Error in pattern_test: Network error 7 (Type: network, Module: pattern_test_module)
2025-08-17 20:50:45,826 - core.error_handler - INFO - error_handler.py:306 - Attempting recovery for network error
2025-08-17 20:50:45,826 - core.error_handler - INFO - error_handler.py:250 - Attempting network error recovery
2025-08-17 20:50:45,826 - core.error_handler - WARNING - error_handler.py:292 - Error in pattern_test: Network error 8 (Type: network, Module: pattern_test_module)
2025-08-17 20:50:45,826 - core.error_handler - INFO - error_handler.py:306 - Attempting recovery for network error
2025-08-17 20:50:45,826 - core.error_handler - INFO - error_handler.py:250 - Attempting network error recovery
2025-08-17 20:50:45,826 - core.error_handler - WARNING - error_handler.py:292 - Error in pattern_test: Network error 9 (Type: network, Module: pattern_test_module)
2025-08-17 20:50:45,826 - core.error_handler - INFO - error_handler.py:306 - Attempting recovery for network error
2025-08-17 20:50:45,826 - core.error_handler - INFO - error_handler.py:250 - Attempting network error recovery
2025-08-17 20:50:45,826 - core.error_handler - ERROR - error_handler.py:323 - Frequent error pattern: network:ConnectionError occurred 10 times
2025-08-17 20:50:45,828 - core.error_handler - WARNING - error_handler.py:292 - Error in pattern_test: Network error 10 (Type: network, Module: pattern_test_module)
2025-08-17 20:50:45,828 - core.error_handler - INFO - error_handler.py:306 - Attempting recovery for network error
2025-08-17 20:50:45,828 - core.error_handler - INFO - error_handler.py:250 - Attempting network error recovery
2025-08-17 20:50:45,828 - core.error_handler - WARNING - error_handler.py:292 - Error in pattern_test: Network error 11 (Type: network, Module: pattern_test_module)
2025-08-17 20:50:45,828 - core.error_handler - INFO - error_handler.py:306 - Attempting recovery for network error
2025-08-17 20:50:45,828 - core.error_handler - INFO - error_handler.py:250 - Attempting network error recovery
2025-08-17 20:52:01,153 - core.power_manager - WARNING - power_manager.py:439 - No brightness control method detected
2025-08-17 20:52:01,154 - core.power_manager - INFO - power_manager.py:86 - PowerManager initialized
2025-08-17 20:52:01,156 - core.error_handler - ERROR - error_handler.py:290 - Error in network_operation: Network connection failed (Type: network, Module: demo_network)
2025-08-17 20:52:01,168 - core.error_handler - INFO - error_handler.py:435 - Attempting to restart module: demo_network
2025-08-17 20:52:01,170 - core.error_handler - WARNING - error_handler.py:292 - Error in config_access: Access denied to configuration file (Type: permission, Module: demo_config)
2025-08-17 20:52:01,170 - core.error_handler - INFO - error_handler.py:435 - Attempting to restart module: demo_config
2025-08-17 20:52:01,170 - core.error_handler - CRITICAL - error_handler.py:288 - Error in memory_allocation: Insufficient memory for operation (Type: memory, Module: demo_memory)
2025-08-17 20:52:01,171 - core.error_handler - INFO - error_handler.py:435 - Attempting to restart module: demo_memory
2025-08-17 20:52:02,143 - core.error_handler - ERROR - error_handler.py:290 - Error in System Health Monitor: High memory usage: 85.2% (Type: memory, Module: )
2025-08-17 20:52:02,144 - core.notification_manager - ERROR - notification_manager.py:382 - Failed to display notification: Cannot create graphics instruction outside the main Kivy thread
2025-08-17 20:52:02,145 - core.error_handler - WARNING - error_handler.py:402 - Unhandled recovery action: RecoveryAction.SYSTEM_RESTART
2025-08-17 20:52:02,173 - core.module_recovery_manager - INFO - module_recovery_manager.py:72 - Registered module network_module for recovery management
2025-08-17 20:52:02,173 - core.module_recovery_manager - INFO - module_recovery_manager.py:72 - Registered module permission_module for recovery management
2025-08-17 20:52:02,174 - core.module_recovery_manager - INFO - module_recovery_manager.py:72 - Registered module persistent_module for recovery management
2025-08-17 20:52:02,175 - core.error_handler - ERROR - error_handler.py:290 - Error in network_module:initialization: Failed to connect to external service (Type: network, Module: network_module)
2025-08-17 20:52:02,182 - core.error_handler - INFO - error_handler.py:435 - Attempting to restart module: network_module
2025-08-17 20:52:02,183 - core.module_recovery_manager - INFO - module_recovery_manager.py:113 - Restarting module network_module
2025-08-17 20:52:02,183 - stosos.modules.network_module - INFO - base_module.py:99 - Restarting module network_module
2025-08-17 20:52:02,183 - stosos.modules.network_module - ERROR - base_module.py:117 - Error during module restart: Failed to connect to external service
2025-08-17 20:52:02,185 - core.error_handler - ERROR - error_handler.py:290 - Error in network_module:module_restart: Failed to connect to external service (Type: network, Module: network_module)
2025-08-17 20:52:02,185 - core.error_handler - INFO - error_handler.py:306 - Attempting recovery for network error
2025-08-17 20:52:02,185 - core.error_handler - INFO - error_handler.py:250 - Attempting network error recovery
2025-08-17 20:52:02,186 - core.module_recovery_manager - ERROR - module_recovery_manager.py:138 - Module network_module restart failed
2025-08-17 20:52:02,187 - core.error_handler - WARNING - error_handler.py:292 - Error in persistent_module:initialization: Persistent failure - cannot initialize (Type: module, Module: persistent_module)
2025-08-17 20:52:02,187 - core.error_handler - INFO - error_handler.py:435 - Attempting to restart module: persistent_module
2025-08-17 20:52:02,187 - core.module_recovery_manager - INFO - module_recovery_manager.py:113 - Restarting module persistent_module
2025-08-17 20:52:02,187 - stosos.modules.persistent_module - INFO - base_module.py:99 - Restarting module persistent_module
2025-08-17 20:52:02,187 - stosos.modules.persistent_module - ERROR - base_module.py:117 - Error during module restart: Persistent failure - cannot initialize
2025-08-17 20:52:02,188 - core.error_handler - WARNING - error_handler.py:292 - Error in persistent_module:module_restart: Persistent failure - cannot initialize (Type: module, Module: persistent_module)
2025-08-17 20:52:02,188 - core.error_handler - INFO - error_handler.py:306 - Attempting recovery for module error
2025-08-17 20:52:02,188 - core.error_handler - INFO - error_handler.py:256 - Attempting module error recovery for context: persistent_module:module_restart
2025-08-17 20:52:02,188 - core.module_recovery_manager - ERROR - module_recovery_manager.py:138 - Module persistent_module restart failed
2025-08-17 20:52:02,188 - core.module_recovery_manager - INFO - module_recovery_manager.py:113 - Restarting module persistent_module
2025-08-17 20:52:02,189 - stosos.modules.persistent_module - INFO - base_module.py:99 - Restarting module persistent_module
2025-08-17 20:52:02,189 - stosos.modules.persistent_module - ERROR - base_module.py:117 - Error during module restart: Persistent failure - cannot initialize
2025-08-17 20:52:02,189 - core.error_handler - WARNING - error_handler.py:292 - Error in persistent_module:module_restart: Persistent failure - cannot initialize (Type: module, Module: persistent_module)
2025-08-17 20:52:02,189 - core.error_handler - INFO - error_handler.py:306 - Attempting recovery for module error
2025-08-17 20:52:02,189 - core.error_handler - INFO - error_handler.py:256 - Attempting module error recovery for context: persistent_module:module_restart
2025-08-17 20:52:02,189 - core.module_recovery_manager - ERROR - module_recovery_manager.py:138 - Module persistent_module restart failed
2025-08-17 20:52:02,189 - core.module_recovery_manager - INFO - module_recovery_manager.py:113 - Restarting module persistent_module
2025-08-17 20:52:02,189 - stosos.modules.persistent_module - INFO - base_module.py:99 - Restarting module persistent_module
2025-08-17 20:52:02,189 - stosos.modules.persistent_module - ERROR - base_module.py:117 - Error during module restart: Persistent failure - cannot initialize
2025-08-17 20:52:02,190 - core.error_handler - WARNING - error_handler.py:292 - Error in persistent_module:module_restart: Persistent failure - cannot initialize (Type: module, Module: persistent_module)
2025-08-17 20:52:02,190 - core.error_handler - INFO - error_handler.py:306 - Attempting recovery for module error
2025-08-17 20:52:02,190 - core.error_handler - INFO - error_handler.py:256 - Attempting module error recovery for context: persistent_module:module_restart
2025-08-17 20:52:02,190 - core.module_recovery_manager - ERROR - module_recovery_manager.py:138 - Module persistent_module restart failed
2025-08-17 20:52:02,190 - core.module_recovery_manager - INFO - module_recovery_manager.py:274 - Fallback mode enabled for module persistent_module
2025-08-17 20:52:02,190 - core.module_recovery_manager - INFO - module_recovery_manager.py:274 - Fallback mode enabled for module persistent_module
2025-08-17 20:52:02,190 - core.module_recovery_manager - INFO - module_recovery_manager.py:88 - Unregistered module network_module
2025-08-17 20:52:02,190 - core.module_recovery_manager - INFO - module_recovery_manager.py:88 - Unregistered module permission_module
2025-08-17 20:52:02,190 - core.module_recovery_manager - INFO - module_recovery_manager.py:88 - Unregistered module persistent_module
2025-08-17 20:52:05,254 - core.error_handler - WARNING - error_handler.py:292 - Error in pattern_demo: Operation timeout #1 (Type: timeout, Module: pattern_test_module)
2025-08-17 20:52:05,254 - core.error_handler - INFO - error_handler.py:435 - Attempting to restart module: pattern_test_module
2025-08-17 20:52:05,255 - core.error_handler - WARNING - error_handler.py:292 - Error in pattern_demo: Operation timeout #2 (Type: timeout, Module: pattern_test_module)
2025-08-17 20:52:05,255 - core.error_handler - WARNING - error_handler.py:292 - Error in pattern_demo: Operation timeout #3 (Type: timeout, Module: pattern_test_module)
2025-08-17 20:52:05,256 - core.error_handler - WARNING - error_handler.py:292 - Error in pattern_demo: Operation timeout #4 (Type: timeout, Module: pattern_test_module)
2025-08-17 20:52:05,256 - core.error_handler - WARNING - error_handler.py:292 - Error in pattern_demo: Operation timeout #5 (Type: timeout, Module: pattern_test_module)
2025-08-17 20:52:05,256 - core.error_handler - WARNING - error_handler.py:321 - Error pattern detected: timeout:TimeoutError occurred 5 times
2025-08-17 20:52:05,257 - core.error_handler - WARNING - error_handler.py:292 - Error in pattern_demo: Operation timeout #6 (Type: timeout, Module: pattern_test_module)
2025-08-17 20:52:05,257 - core.error_handler - WARNING - error_handler.py:292 - Error in pattern_demo: Operation timeout #7 (Type: timeout, Module: pattern_test_module)
2025-08-17 20:52:05,257 - core.error_handler - WARNING - error_handler.py:292 - Error in pattern_demo: Operation timeout #8 (Type: timeout, Module: pattern_test_module)
2025-08-17 20:52:05,258 - core.error_handler - WARNING - error_handler.py:292 - Error in pattern_demo: Operation timeout #9 (Type: timeout, Module: pattern_test_module)
2025-08-17 20:52:05,258 - core.error_handler - WARNING - error_handler.py:292 - Error in pattern_demo: Operation timeout #10 (Type: timeout, Module: pattern_test_module)
2025-08-17 20:52:05,258 - core.error_handler - ERROR - error_handler.py:323 - Frequent error pattern: timeout:TimeoutError occurred 10 times
2025-08-17 20:52:05,259 - core.error_handler - WARNING - error_handler.py:292 - Error in pattern_demo: Operation timeout #11 (Type: timeout, Module: pattern_test_module)
2025-08-17 20:52:05,259 - core.error_handler - WARNING - error_handler.py:292 - Error in pattern_demo: Operation timeout #12 (Type: timeout, Module: pattern_test_module)
2025-08-17 20:52:05,259 - core.error_handler - WARNING - error_handler.py:292 - Error in pattern_demo: Operation timeout #13 (Type: timeout, Module: pattern_test_module)
2025-08-17 20:52:05,260 - core.error_handler - WARNING - error_handler.py:292 - Error in pattern_demo: Operation timeout #14 (Type: timeout, Module: pattern_test_module)
2025-08-17 20:52:05,260 - core.error_handler - WARNING - error_handler.py:292 - Error in pattern_demo: Operation timeout #15 (Type: timeout, Module: pattern_test_module)
2025-08-17 20:52:07,285 - core.module_recovery_manager - INFO - module_recovery_manager.py:72 - Registered module stressed_module for recovery management
2025-08-17 20:52:07,287 - core.error_handler - WARNING - error_handler.py:292 - Error in stressed_module:stress_test_0: Persistent failure - cannot initialize (Type: module, Module: stressed_module)
2025-08-17 20:52:07,287 - core.error_handler - INFO - error_handler.py:435 - Attempting to restart module: stressed_module
2025-08-17 20:52:07,291 - core.error_handler - WARNING - error_handler.py:321 - Error pattern detected: module:Exception occurred 5 times
2025-08-17 20:52:07,293 - core.error_handler - WARNING - error_handler.py:292 - Error in stressed_module:stress_test_1: Persistent failure - cannot initialize (Type: module, Module: stressed_module)
2025-08-17 20:52:07,293 - core.error_handler - INFO - error_handler.py:306 - Attempting recovery for module error
2025-08-17 20:52:07,293 - core.error_handler - INFO - error_handler.py:256 - Attempting module error recovery for context: stressed_module:stress_test_1
2025-08-17 20:52:07,293 - core.module_recovery_manager - INFO - module_recovery_manager.py:348 - Automatically restarting failed module stressed_module
2025-08-17 20:52:07,293 - core.module_recovery_manager - INFO - module_recovery_manager.py:113 - Restarting module stressed_module
2025-08-17 20:52:07,293 - stosos.modules.stressed_module - INFO - base_module.py:99 - Restarting module stressed_module
2025-08-17 20:52:07,293 - stosos.modules.stressed_module - ERROR - base_module.py:117 - Error during module restart: Persistent failure - cannot initialize
2025-08-17 20:52:07,294 - core.error_handler - WARNING - error_handler.py:292 - Error in stressed_module:module_restart: Persistent failure - cannot initialize (Type: module, Module: stressed_module)
2025-08-17 20:52:07,294 - core.error_handler - INFO - error_handler.py:306 - Attempting recovery for module error
2025-08-17 20:52:07,294 - core.error_handler - INFO - error_handler.py:256 - Attempting module error recovery for context: stressed_module:module_restart
2025-08-17 20:52:07,294 - core.module_recovery_manager - ERROR - module_recovery_manager.py:138 - Module stressed_module restart failed
2025-08-17 20:52:07,295 - core.error_handler - WARNING - error_handler.py:292 - Error in stressed_module:stress_test_2: Persistent failure - cannot initialize (Type: module, Module: stressed_module)
2025-08-17 20:52:07,295 - core.error_handler - INFO - error_handler.py:306 - Attempting recovery for module error
2025-08-17 20:52:07,295 - core.error_handler - INFO - error_handler.py:256 - Attempting module error recovery for context: stressed_module:stress_test_2
2025-08-17 20:52:07,296 - core.error_handler - WARNING - error_handler.py:292 - Error in stressed_module:stress_test_3: Persistent failure - cannot initialize (Type: module, Module: stressed_module)
2025-08-17 20:52:07,296 - core.error_handler - INFO - error_handler.py:306 - Attempting recovery for module error
2025-08-17 20:52:07,296 - core.error_handler - INFO - error_handler.py:256 - Attempting module error recovery for context: stressed_module:stress_test_3
2025-08-17 20:52:07,296 - core.error_handler - WARNING - error_handler.py:292 - Error in stressed_module:stress_test_4: Persistent failure - cannot initialize (Type: module, Module: stressed_module)
2025-08-17 20:52:07,296 - core.error_handler - INFO - error_handler.py:306 - Attempting recovery for module error
2025-08-17 20:52:07,296 - core.error_handler - INFO - error_handler.py:256 - Attempting module error recovery for context: stressed_module:stress_test_4
2025-08-17 20:52:07,296 - core.error_handler - ERROR - error_handler.py:323 - Frequent error pattern: module:Exception occurred 10 times
2025-08-17 20:52:07,299 - core.module_recovery_manager - INFO - module_recovery_manager.py:274 - Fallback mode enabled for module stressed_module
2025-08-17 20:52:07,299 - core.module_recovery_manager - INFO - module_recovery_manager.py:88 - Unregistered module stressed_module
